Workbook

Sheet Read Me
C2: DAMM v1.7 — Scoring Workbook
C3: Digital Agriculture Maturity Model · draft for review · August 2026
C5: This file is the Egypt worked example, compiled 22 August 2026.
C7: The four steps
C8: 1 · ASSEMBLE | D8: Fill the six yellow columns on the scoring sheet: Value, Source, Source URL, Tier, Year, Assessor level. Every indicator gets a value, a source and a year — or a recorded gap. No level may exist without a recorded value.
C9: 2 · DERIVE | D9: Automatic. Evidence class, level, staleness, pillar bands, the layer profile, prerequisite status and the use-case matrix all compute by formula. Nothing here is typed.
C10: 3 · REPORT | D10: The diagnostic report renders from this workbook. It is the deliverable; this file is the instrument behind it.
C11: 4 · USE | D11: The task team leader takes the report into roadmap preparation, closes the verify list on mission, and executes the refresh list.
C13: What to type, and where
C14: Yellow cells, blue text | D14: The only cells an assessor edits: Value, Source, Source URL, Tier, Year, Assessor level (columns M–R of the scoring sheet).
C15: Everything else | D15: Model reference or derived by formula. Do not overwrite: a typed level that contradicts its value is the defect this model exists to prevent.
C16: Value | D16: A number, a citation ("NDPA 2023 in force; NDPC enforcing"), or a recorded gap beginning DATA GAP — followed by the sources actually searched.
C17: Tier | D17: T1–T5 per the Tiers sheet. Reported, never weighted. Machine-fetched rows arrive with the tier already filled by the pipeline.
C18: Assessor level | D18: 1–5, for ladder indicators only. Threshold indicators score themselves from the value.
C20: Quality control — gate sign-off
D21: Automated checks run at render time and block the report on failure. The three human gates are recorded here (QC Protocol).
C22: Gate | D22: What it certifies | E22: Name | F22: Date | G22: Note
C23: G1 | D23: Assessor has confirmed every machine-filled row: value, source, year, tier; every recorded gap accepted or re-searched.
C24: G2 | D24: A second reviewer has re-checked 100% of prerequisite rows and 100% of judged rows, plus a 15% sample of the remainder.
C25: G3 | D25: Task team leader sign-off against the four prohibitions, before anything leaves the team.
C27: The four prohibitions
D28: · No cross-country ranking.
D29: · No band used as a project development objective, disbursement-linked indicator, or disbursement condition.
D30: · No automatic financing decisions.
D31: · No public claim before human review.

Sheet Config
B1: Config — every constant with its meaning
B2: Assessment year | C2: 2026 | D2: ENTRY (yellow). Staleness is measured against this year.
B3: Staleness limit (years) | C3: 3 | D3: A reading older than this is flagged STALE. One rule for all indicators.
B4: Readiness threshold | C4: 2.6 | D4: A use-case column whose bearing indicators average below this reads Partial.
B5: Leapfrog threshold | C5: 1.5 | D5: |mean(Foundation) − mean(Transformation)| above this raises a structural flag.
B6: Band: Nascent | C6: 1.0 – <1.8 | D6: Half-open bands; a pillar band in parentheses means judged, gap and held rows outnumber the levelled measured and documented ones.
B7: Band: Emerging | C7: 1.8 – <2.6
B8: Band: Established | C8: 2.6 – <3.4
B9: Band: Advanced | C9: 3.4 – <4.2
B10: Band: Transformative | C10: 4.2 – 5.0
B11: Universal prerequisites | C11: 2.1, 2.9, 4.1 | D11: Absence blocks every use-case column. A universal prerequisite at Present (narrow) caps every column at Partial.
B12: AI-enabled services | C12: 7.12 binds AGI | D12: Ruling pending ratification: the consent-and-rights prerequisite binds the agricultural-intelligence column.

Sheet Ladder
B1: The shared ladder — scoring an indicator that is not a measurement
B2: Ask in stages: presence first, then quality, then scale. Stop at the first rung the evidence does not support.
B4: Level | C4: Condition | D4: Evidence required
B5: 1 | C5: Absent | D5: The search that established absence: sources consulted, in order.
B6: 2 | C6: Announced | D6: The announcement, draft or commitment, cited.
B7: 3 | C7: Adopted, or operating narrowly | D7: The instrument or system itself, with its adoption date or its operating footprint.
B8: 4 | C8: Operating with quality | D8: Governance, funding and institutionalisation — the evidence that it is run, not just live.
B9: 5 | C9: Operating at scale, with evidence of use | D9: Coverage or reach in the indicator's own unit, from a source that is not the operator's own claim.
B11: A scale figure reported only by the operator of the service does not carry rung 5.

Sheet Tiers
B1: Source tiers — what may carry what
B2: Tiers are reported beside the evidence class and never weighted. Search in tier order and stop when found; a dead end is recorded as a gap with its trail.
B4: Tier | C4: What it is | D4: Typical sources | E4: Admissible for
B5: T1 | C5: Official statistics & international databases | D5: FAOSTAT · AQUASTAT · World Bank WDI/ID4D/Findex · ITU · UN DESA · national statistical offices | E5: Any claim. The default for every number.
B6: T2 | C6: Peer-reviewed literature & IO flagship reports | D6: Journals · systematic reviews · World Bank / FAO / IFPRI / CGIAR flagships · evaluated impact studies | E6: Any claim. Required for impact and effectiveness claims.
B7: T3 | C7: Government legal, policy & budget artefacts | D7: Gazetted laws · adopted strategies · budgets · regulator reports · official programme pages | E7: Presence facts, policy intent, programme design — not outcomes.
B8: T4 | C8: Reputable grey literature | D8: GSMA · GIZ · USAID · AGRA · AfDB · donor evaluations · established industry analyses | E8: Context and sector narrative, flagged as T4; presence facts where T3 is silent.
B9: T5 | C9: News, vendor & market material | D9: Press · company sites · market-research releases · blogs | E9: Initiative register only, existence facts only. A T5-only citation derives the class Judged, never Documented.
C11: · Every citation is a deep link to the document, with an access date. A link that resolves only to a domain root is not a citation.
C12: · A load-bearing number needs two independent T1–T2 confirmations, or it ships flagged single-source.
C13: · Vintage beats tier at the margin for narrative; the scored row still records the official figure and its staleness honestly.

Sheet Egypt
A1: Egypt — DAMM v1.7 assessment
A2: Edit only the yellow columns (M–R). Everything else is model reference or derived by formula.
A4: ID | B4: Indicator | C4: Pillar | D4: Layer | E4: Use cases | F4: Prereq | G4: Meth | H4: Dir | I4: L2 | J4: L3 | K4: L4 | L4: L5 | M4: Value | N4: Source | O4: Source URL | P4: Tier | Q4: Year | R4: Assessor level | S4: Class | T4: Level | U4: Stale | V4: b_ADV | W4: b_SMF | X4: b_MKT | Y4: b_SCM | Z4: b_FIN | AA4: b_AGI | AB4: Open definition question (for ratification) | AC4: Ratification hold
A5: 1.1 | B5: Agriculture value added per worker (USD) | C5: A1 | D5: Foundation | E5: NEED | G5: T | H5: H | I5: 1000 | J5: 2500 | K5: 5000 | L5: 10000 | M5: 8942.4183 | N5: World Bank WDI NV.AGR.EMPL.KD | O5: https://api.worldbank.org/v2/country/EGY/indicator/NV.AGR.EMPL.KD?format=json&mrnev=1&per_page=5 | P5: T1 | Q5: 2025 | S5: =IF($M5="","",IF(ISNUMBER($M5),"Measured",IF(ISNUMBER(SEARCH("DATA GAP",UPPER($M5))),"Gap",IF(AND($N5<>"",$P5<>"T5"),"Documented","Judged")))) -> Measured | T5: =IF($AC5<>"","",IF(OR($S5="",$S5="Gap"),"",IF($S5="Measured",1+IF($H5="H",IF($M5>=$I5,1,0)+IF($M5>=$J5,1,0)+IF($M5>=$K5,1,0)+IF($M5>=$L5,1,0),IF($M5<=$I5,1,0)+IF($M5<=$J5,1,0)+IF($M5<=$K5,1,0)+IF($M5<=$L5,1,0)),IF($R5<>"",$R5,"")))) -> 4 | U5: =IF(OR($S5="",$S5="Gap",$Q5=""),"",IF($Q5<Config!$C$2-Config!$C$3,"STALE","")) | V5: =IF(OR(ISNUMBER(SEARCH("ALL",$E5)),ISNUMBER(SEARCH("ADV",$E5))),1,0) -> 0 | W5: =IF(OR(ISNUMBER(SEARCH("ALL",$E5)),ISNUMBER(SEARCH("SMF",$E5))),1,0) -> 0 | X5: =IF(OR(ISNUMBER(SEARCH("ALL",$E5)),ISNUMBER(SEARCH("MKT",$E5))),1,0) -> 0 | Y5: =IF(OR(ISNUMBER(SEARCH("ALL",$E5)),ISNUMBER(SEARCH("SCM",$E5))),1,0) -> 0 | Z5: =IF(OR(ISNUMBER(SEARCH("ALL",$E5)),ISNUMBER(SEARCH("FIN",$E5))),1,0) -> 0 | AA5: =IF(OR(ISNUMBER(SEARCH("ALL",$E5)),ISNUMBER(SEARCH("AGI",$E5))),1,0) -> 0 | AB5: The name says "Agriculture... (USD)" but both countries record WDI NV.AGR.EMPL.KD, which covers agriculture, forestry AND fishing and is denominated in constant 2015 US$ — neither the sector scope nor the price basis is stated in the name or in the bare-USD thresholds, and neither row carries…
A6: 1.2 | B6: Cereal yield (kg/ha) | C6: A1 | D6: Foundation | E6: NEED | G6: T | H6: H | I6: 1500 | J6: 3000 | K6: 4500 | L6: 6000 | M6: 7402.2 | N6: World Bank WDI AG.YLD.CREL.KG | O6: https://api.worldbank.org/v2/country/EGY/indicator/AG.YLD.CREL.KG?format=json&mrnev=1&per_page=5 | P6: T1 | Q6: 2023 | S6: =IF($M6="","",IF(ISNUMBER($M6),"Measured",IF(ISNUMBER(SEARCH("DATA GAP",UPPER($M6))),"Gap",IF(AND($N6<>"",$P6<>"T5"),"Documented","Judged")))) -> Measured | T6: =IF($AC6<>"","",IF(OR($S6="",$S6="Gap"),"",IF($S6="Measured",1+IF($H6="H",IF($M6>=$I6,1,0)+IF($M6>=$J6,1,0)+IF($M6>=$K6,1,0)+IF($M6>=$L6,1,0),IF($M6<=$I6,1,0)+IF($M6<=$J6,1,0)+IF($M6<=$K6,1,0)+IF($M6<=$L6,1,0)),IF($R6<>"",$R6,"")))) -> 5 | U6: =IF(OR($S6="",$S6="Gap",$Q6=""),"",IF($Q6<Config!$C$2-Config!$C$3,"STALE","")) | V6: =IF(OR(ISNUMBER(SEARCH("ALL",$E6)),ISNUMBER(SEARCH("ADV",$E6))),1,0) -> 0 | W6: =IF(OR(ISNUMBER(SEARCH("ALL",$E6)),ISNUMBER(SEARCH("SMF",$E6))),1,0) -> 0 | X6: =IF(OR(ISNUMBER(SEARCH("ALL",$E6)),ISNUMBER(SEARCH("MKT",$E6))),1,0) -> 0 | Y6: =IF(OR(ISNUMBER(SEARCH("ALL",$E6)),ISNUMBER(SEARCH("SCM",$E6))),1,0) -> 0 | Z6: =IF(OR(ISNUMBER(SEARCH("ALL",$E6)),ISNUMBER(SEARCH("FIN",$E6))),1,0) -> 0 | AA6: =IF(OR(ISNUMBER(SEARCH("ALL",$E6)),ISNUMBER(SEARCH("AGI",$E6))),1,0) -> 0
A7: 1.3 | B7: Employment in agriculture (%) | C7: A1 | D7: Foundation | E7: NEED | G7: T | H7: L | I7: 45 | J7: 30 | K7: 15 | L7: 5 | M7: 17.524644 | N7: World Bank WDI SL.AGR.EMPL.ZS (ILO modeled estimate) | O7: https://api.worldbank.org/v2/country/EGY/indicator/SL.AGR.EMPL.ZS?format=json&mrnev=1&per_page=5 | P7: T1 | Q7: 2025 | S7: =IF($M7="","",IF(ISNUMBER($M7),"Measured",IF(ISNUMBER(SEARCH("DATA GAP",UPPER($M7))),"Gap",IF(AND($N7<>"",$P7<>"T5"),"Documented","Judged")))) -> Measured | T7: =IF($AC7<>"","",IF(OR($S7="",$S7="Gap"),"",IF($S7="Measured",1+IF($H7="H",IF($M7>=$I7,1,0)+IF($M7>=$J7,1,0)+IF($M7>=$K7,1,0)+IF($M7>=$L7,1,0),IF($M7<=$I7,1,0)+IF($M7<=$J7,1,0)+IF($M7<=$K7,1,0)+IF($M7<=$L7,1,0)),IF($R7<>"",$R7,"")))) -> 3 | U7: =IF(OR($S7="",$S7="Gap",$Q7=""),"",IF($Q7<Config!$C$2-Config!$C$3,"STALE","")) | V7: =IF(OR(ISNUMBER(SEARCH("ALL",$E7)),ISNUMBER(SEARCH("ADV",$E7))),1,0) -> 0 | W7: =IF(OR(ISNUMBER(SEARCH("ALL",$E7)),ISNUMBER(SEARCH("SMF",$E7))),1,0) -> 0 | X7: =IF(OR(ISNUMBER(SEARCH("ALL",$E7)),ISNUMBER(SEARCH("MKT",$E7))),1,0) -> 0 | Y7: =IF(OR(ISNUMBER(SEARCH("ALL",$E7)),ISNUMBER(SEARCH("SCM",$E7))),1,0) -> 0 | Z7: =IF(OR(ISNUMBER(SEARCH("ALL",$E7)),ISNUMBER(SEARCH("FIN",$E7))),1,0) -> 0 | AA7: =IF(OR(ISNUMBER(SEARCH("ALL",$E7)),ISNUMBER(SEARCH("AGI",$E7))),1,0) -> 0 | AB7: The name omits the denominator (% of total employment), the recorded series covers ISIC-A (agriculture, hunting, forestry and fishing) rather than agriculture alone, and both rows carry an ILO MODELLED 2025 nowcast under cls "Measured" — the register's highest evidence class — which the…
A8: 1.4 | B8: Food production index (2014-16=100) | C8: A1 | D8: Foundation | E8: NEED | G8: T | H8: H | I8: 95 | J8: 105 | K8: 115 | L8: 130 | M8: 109.07 | N8: World Bank WDI AG.PRD.FOOD.XD | O8: https://api.worldbank.org/v2/country/EGY/indicator/AG.PRD.FOOD.XD?format=json&mrnev=1&per_page=5 | P8: T1 | Q8: 2022 | S8: =IF($M8="","",IF(ISNUMBER($M8),"Measured",IF(ISNUMBER(SEARCH("DATA GAP",UPPER($M8))),"Gap",IF(AND($N8<>"",$P8<>"T5"),"Documented","Judged")))) -> Measured | T8: =IF($AC8<>"","",IF(OR($S8="",$S8="Gap"),"",IF($S8="Measured",1+IF($H8="H",IF($M8>=$I8,1,0)+IF($M8>=$J8,1,0)+IF($M8>=$K8,1,0)+IF($M8>=$L8,1,0),IF($M8<=$I8,1,0)+IF($M8<=$J8,1,0)+IF($M8<=$K8,1,0)+IF($M8<=$L8,1,0)),IF($R8<>"",$R8,"")))) -> 3 | U8: =IF(OR($S8="",$S8="Gap",$Q8=""),"",IF($Q8<Config!$C$2-Config!$C$3,"STALE","")) -> STALE | V8: =IF(OR(ISNUMBER(SEARCH("ALL",$E8)),ISNUMBER(SEARCH("ADV",$E8))),1,0) -> 0 | W8: =IF(OR(ISNUMBER(SEARCH("ALL",$E8)),ISNUMBER(SEARCH("SMF",$E8))),1,0) -> 0 | X8: =IF(OR(ISNUMBER(SEARCH("ALL",$E8)),ISNUMBER(SEARCH("MKT",$E8))),1,0) -> 0 | Y8: =IF(OR(ISNUMBER(SEARCH("ALL",$E8)),ISNUMBER(SEARCH("SCM",$E8))),1,0) -> 0 | Z8: =IF(OR(ISNUMBER(SEARCH("ALL",$E8)),ISNUMBER(SEARCH("FIN",$E8))),1,0) -> 0 | AA8: =IF(OR(ISNUMBER(SEARCH("ALL",$E8)),ISNUMBER(SEARCH("AGI",$E8))),1,0) -> 0
A9: 1.5 | B9: Post-harvest loss rate (%) | C9: A1 | D9: Foundation | E9: NEED | G9: T | H9: L | I9: 30 | J9: 20 | K9: 12 | L9: 5 | M9: No single national post-harvest loss rate exists. Cereals (labelled, admissible): ~10% pre- and post-harvest losses (SADS 2030, estimate c.2009); wheat losses in traditional shona storage 10-20% (FAO 2019). Horticulture: | N9: FAO (2019), Food loss and waste in Egypt, CA4310EN, FAO Representation in Egypt | O9: https://openknowledge.fao.org/server/api/core/bitstreams/3d94597d-cc5c-420a-8faa-0fe284d5c921/content | P9: T2 | Q9: 2019 | R9: 4 | S9: =IF($M9="","",IF(ISNUMBER($M9),"Measured",IF(ISNUMBER(SEARCH("DATA GAP",UPPER($M9))),"Gap",IF(AND($N9<>"",$P9<>"T5"),"Documented","Judged")))) -> Documented | T9: =IF($AC9<>"","",IF(OR($S9="",$S9="Gap"),"",IF($S9="Measured",1+IF($H9="H",IF($M9>=$I9,1,0)+IF($M9>=$J9,1,0)+IF($M9>=$K9,1,0)+IF($M9>=$L9,1,0),IF($M9<=$I9,1,0)+IF($M9<=$J9,1,0)+IF($M9<=$K9,1,0)+IF($M9<=$L9,1,0)),IF($R9<>"",$R9,"")))) -> 4 | U9: =IF(OR($S9="",$S9="Gap",$Q9=""),"",IF($Q9<Config!$C$2-Config!$C$3,"STALE","")) -> STALE | V9: =IF(OR(ISNUMBER(SEARCH("ALL",$E9)),ISNUMBER(SEARCH("ADV",$E9))),1,0) -> 0 | W9: =IF(OR(ISNUMBER(SEARCH("ALL",$E9)),ISNUMBER(SEARCH("SMF",$E9))),1,0) -> 0 | X9: =IF(OR(ISNUMBER(SEARCH("ALL",$E9)),ISNUMBER(SEARCH("MKT",$E9))),1,0) -> 0 | Y9: =IF(OR(ISNUMBER(SEARCH("ALL",$E9)),ISNUMBER(SEARCH("SCM",$E9))),1,0) -> 0 | Z9: =IF(OR(ISNUMBER(SEARCH("ALL",$E9)),ISNUMBER(SEARCH("FIN",$E9))),1,0) -> 0 | AA9: =IF(OR(ISNUMBER(SEARCH("ALL",$E9)),ISNUMBER(SEARCH("AGI",$E9))),1,0) -> 0 | AB9: The name asserts an all-crop national post-harvest loss rate; both countries record cereals-only figures, and Egypt's scored figure is described by its own source as covering pre- AND post-harvest losses.
A10: 1.6 | B10: Smallholder access to formal markets (%) | C10: A1 | D10: Foundation | E10: NEED,MKT | G10: T | H10: H | I10: 20 | J10: 40 | K10: 60 | L10: 80 | M10: No national figure. Upper Egypt (regional, labelled): 6% of surveyed smallholder households participate in contract farming (farm household survey Apr-May 2018, seven Upper Egypt governorates, n=2,237 households; IFPRI). | N10: Tabe-Ojong, M.P. Jr. & Abay, K.A. (2023), Smallholder farmers' participation in profitable value chains and contract farming: Evidence from irrigated agriculture in Egypt, IFPRI MENA Working Paper 42 | O10: https://cgspace.cgiar.org/items/b1bc85c0-7505-4fb7-9957-d7588eea9756 | P10: T2 | Q10: 2018 | R10: 1 | S10: =IF($M10="","",IF(ISNUMBER($M10),"Measured",IF(ISNUMBER(SEARCH("DATA GAP",UPPER($M10))),"Gap",IF(AND($N10<>"",$P10<>"T5"),"Documented","Judged")))) -> Documented | T10: =IF($AC10<>"","",IF(OR($S10="",$S10="Gap"),"",IF($S10="Measured",1+IF($H10="H",IF($M10>=$I10,1,0)+IF($M10>=$J10,1,0)+IF($M10>=$K10,1,0)+IF($M10>=$L10,1,0),IF($M10<=$I10,1,0)+IF($M10<=$J10,1,0)+IF($M10<=$K10,1,0)+IF($M10<=$L10,1,0)),IF($R10<>"",$R10,"")))) -> 1 | U10: =IF(OR($S10="",$S10="Gap",$Q10=""),"",IF($Q10<Config!$C$2-Config!$C$3,"STALE","")) -> STALE | V10: =IF(OR(ISNUMBER(SEARCH("ALL",$E10)),ISNUMBER(SEARCH("ADV",$E10))),1,0) -> 0 | W10: =IF(OR(ISNUMBER(SEARCH("ALL",$E10)),ISNUMBER(SEARCH("SMF",$E10))),1,0) -> 0 | X10: =IF(OR(ISNUMBER(SEARCH("ALL",$E10)),ISNUMBER(SEARCH("MKT",$E10))),1,0) -> 1 | Y10: =IF(OR(ISNUMBER(SEARCH("ALL",$E10)),ISNUMBER(SEARCH("SCM",$E10))),1,0) -> 0 | Z10: =IF(OR(ISNUMBER(SEARCH("ALL",$E10)),ISNUMBER(SEARCH("FIN",$E10))),1,0) -> 0 | AA10: =IF(OR(ISNUMBER(SEARCH("ALL",$E10)),ISNUMBER(SEARCH("AGI",$E10))),1,0) -> 0 | AB10: The name asserts national smallholder ACCESS to formal markets; Egypt records a regional contract-farming PARTICIPATION rate from seven governorates and Nigeria a 2012/13 channel-of-sale share — two different constructs, neither of which is access, and neither national in Egypt's case.
A11: 1.7 | B11: Agricultural credit access (% farmers) | C11: A1 | D11: Foundation | E11: NEED,FIN | G11: T | H11: H | I11: 10 | J11: 25 | K11: 40 | L11: 60 | M11: No direct '% of farmers with agricultural credit' figure exists for Egypt. Nearest labelled figures: only 2.3% of rural individuals aged 15+ had loans from formal financial institutions (ELMPS 2018, CAPMAS national panel | N11: Mansour, S., Samak, N. & Gad, N. (2024), Credit Choices in Rural Egypt: A Comparative Study of Formal and Informal Borrowing, Journal of Risk and Financial Management 17(11): 487 | O11: https://doi.org/10.3390/jrfm17110487 | P11: T2 | Q11: 2018 | R11: 1 | S11: =IF($M11="","",IF(ISNUMBER($M11),"Measured",IF(ISNUMBER(SEARCH("DATA GAP",UPPER($M11))),"Gap",IF(AND($N11<>"",$P11<>"T5"),"Documented","Judged")))) -> Documented | T11: =IF($AC11<>"","",IF(OR($S11="",$S11="Gap"),"",IF($S11="Measured",1+IF($H11="H",IF($M11>=$I11,1,0)+IF($M11>=$J11,1,0)+IF($M11>=$K11,1,0)+IF($M11>=$L11,1,0),IF($M11<=$I11,1,0)+IF($M11<=$J11,1,0)+IF($M11<=$K11,1,0)+IF($M11<=$L11,1,0)),IF($R11<>"",$R11,"")))) -> 1 | U11: =IF(OR($S11="",$S11="Gap",$Q11=""),"",IF($Q11<Config!$C$2-Config!$C$3,"STALE","")) -> STALE | V11: =IF(OR(ISNUMBER(SEARCH("ALL",$E11)),ISNUMBER(SEARCH("ADV",$E11))),1,0) -> 0 | W11: =IF(OR(ISNUMBER(SEARCH("ALL",$E11)),ISNUMBER(SEARCH("SMF",$E11))),1,0) -> 0 | X11: =IF(OR(ISNUMBER(SEARCH("ALL",$E11)),ISNUMBER(SEARCH("MKT",$E11))),1,0) -> 0 | Y11: =IF(OR(ISNUMBER(SEARCH("ALL",$E11)),ISNUMBER(SEARCH("SCM",$E11))),1,0) -> 0 | Z11: =IF(OR(ISNUMBER(SEARCH("ALL",$E11)),ISNUMBER(SEARCH("FIN",$E11))),1,0) -> 1 | AA11: =IF(OR(ISNUMBER(SEARCH("ALL",$E11)),ISNUMBER(SEARCH("AGI",$E11))),1,0) -> 0 | AB11: The name asserts a share of FARMERS with credit ACCESS; Egypt records rural adults aged 15+ (a population that includes non-farmers) and Nigeria records smallholder households, and both measure borrowing/use rather than access.
A12: 1.8 | B12: Farmers using climate-smart practices (%) | C12: A1 | D12: Foundation | E12: NEED,ADV | G12: T | H12: H | I12: 20 | J12: 40 | K12: 60 | L12: 80 | M12: No all-practice national CSA rate. Practice-specific (labelled): raised-bed wheat cultivation tripled 113,500 ha (2013/14) to 334,000 ha (2016/17) ~46% of wheat area; laser levelling and deficit-irrigation adoption documented | N12: USDA GAIN Egypt grain report (primary PDF); FAO/WB corroboration | O12: https://apps.fas.usda.gov/newgainapi/api/report/downloadreportbyfilename?filename=Grain%20and%20Feed%20Annual_Cairo_Egypt_3-15-2017.pdf | P12: T4 | Q12: 2017 | S12: =IF($M12="","",IF(ISNUMBER($M12),"Measured",IF(ISNUMBER(SEARCH("DATA GAP",UPPER($M12))),"Gap",IF(AND($N12<>"",$P12<>"T5"),"Documented","Judged")))) -> Documented | T12: =IF($AC12<>"","",IF(OR($S12="",$S12="Gap"),"",IF($S12="Measured",1+IF($H12="H",IF($M12>=$I12,1,0)+IF($M12>=$J12,1,0)+IF($M12>=$K12,1,0)+IF($M12>=$L12,1,0),IF($M12<=$I12,1,0)+IF($M12<=$J12,1,0)+IF($M12<=$K12,1,0)+IF($M12<=$L12,1,0)),IF($R12<>"",$R12,"")))) | U12: =IF(OR($S12="",$S12="Gap",$Q12=""),"",IF($Q12<Config!$C$2-Config!$C$3,"STALE","")) -> STALE | V12: =IF(OR(ISNUMBER(SEARCH("ALL",$E12)),ISNUMBER(SEARCH("ADV",$E12))),1,0) -> 1 | W12: =IF(OR(ISNUMBER(SEARCH("ALL",$E12)),ISNUMBER(SEARCH("SMF",$E12))),1,0) -> 0 | X12: =IF(OR(ISNUMBER(SEARCH("ALL",$E12)),ISNUMBER(SEARCH("MKT",$E12))),1,0) -> 0 | Y12: =IF(OR(ISNUMBER(SEARCH("ALL",$E12)),ISNUMBER(SEARCH("SCM",$E12))),1,0) -> 0 | Z12: =IF(OR(ISNUMBER(SEARCH("ALL",$E12)),ISNUMBER(SEARCH("FIN",$E12))),1,0) -> 0 | AA12: =IF(OR(ISNUMBER(SEARCH("ALL",$E12)),ISNUMBER(SEARCH("AGI",$E12))),1,0) -> 0 | AB12: The name counts FARMERS adopting climate-smart practices; Egypt records a share of WHEAT AREA under a single practice and Nigeria a share of farmers in two zones adopting at least one climate-resilient crop TRAIT — land, practice-basket and geographic scope all differ from the name. | AC12: HOLD
A13: 8.1 | B13: Prevalence of undernourishment (%) | C13: A1 | D13: Foundation | E13: NEED | G13: T | H13: L | I13: 25 | J13: 15 | K13: 7.5 | L13: 2.5 | M13: 9.4 | N13: World Bank WDI SN.ITK.DEFC.ZS | O13: https://api.worldbank.org/v2/country/EGY/indicator/SN.ITK.DEFC.ZS?format=json&mrnev=1&per_page=5 | P13: T1 | Q13: 2023 | S13: =IF($M13="","",IF(ISNUMBER($M13),"Measured",IF(ISNUMBER(SEARCH("DATA GAP",UPPER($M13))),"Gap",IF(AND($N13<>"",$P13<>"T5"),"Documented","Judged")))) -> Measured | T13: =IF($AC13<>"","",IF(OR($S13="",$S13="Gap"),"",IF($S13="Measured",1+IF($H13="H",IF($M13>=$I13,1,0)+IF($M13>=$J13,1,0)+IF($M13>=$K13,1,0)+IF($M13>=$L13,1,0),IF($M13<=$I13,1,0)+IF($M13<=$J13,1,0)+IF($M13<=$K13,1,0)+IF($M13<=$L13,1,0)),IF($R13<>"",$R13,"")))) -> 3 | U13: =IF(OR($S13="",$S13="Gap",$Q13=""),"",IF($Q13<Config!$C$2-Config!$C$3,"STALE","")) | V13: =IF(OR(ISNUMBER(SEARCH("ALL",$E13)),ISNUMBER(SEARCH("ADV",$E13))),1,0) -> 0 | W13: =IF(OR(ISNUMBER(SEARCH("ALL",$E13)),ISNUMBER(SEARCH("SMF",$E13))),1,0) -> 0 | X13: =IF(OR(ISNUMBER(SEARCH("ALL",$E13)),ISNUMBER(SEARCH("MKT",$E13))),1,0) -> 0 | Y13: =IF(OR(ISNUMBER(SEARCH("ALL",$E13)),ISNUMBER(SEARCH("SCM",$E13))),1,0) -> 0 | Z13: =IF(OR(ISNUMBER(SEARCH("ALL",$E13)),ISNUMBER(SEARCH("FIN",$E13))),1,0) -> 0 | AA13: =IF(OR(ISNUMBER(SEARCH("ALL",$E13)),ISNUMBER(SEARCH("AGI",$E13))),1,0) -> 0
A14: 8.5 | B14: Women who own land (% holders) | C14: A1 | D14: Foundation | E14: NEED,EQ | G14: T | H14: H | I14: 10 | J14: 25 | K14: 40 | L14: 50 | M14: 3.94 | N14: FAOSTAT, World Census of Agriculture domain — Egypt, item 'Civil holders, female', element 'Percent of total persons (holders)', Agricultural Census 2009/10 (CAPMAS) | O14: https://bulks-faostat.fao.org/production/World_Census_Agriculture_E_All_Data.zip | P14: T1 | Q14: 2010 | S14: =IF($M14="","",IF(ISNUMBER($M14),"Measured",IF(ISNUMBER(SEARCH("DATA GAP",UPPER($M14))),"Gap",IF(AND($N14<>"",$P14<>"T5"),"Documented","Judged")))) -> Measured | T14: =IF($AC14<>"","",IF(OR($S14="",$S14="Gap"),"",IF($S14="Measured",1+IF($H14="H",IF($M14>=$I14,1,0)+IF($M14>=$J14,1,0)+IF($M14>=$K14,1,0)+IF($M14>=$L14,1,0),IF($M14<=$I14,1,0)+IF($M14<=$J14,1,0)+IF($M14<=$K14,1,0)+IF($M14<=$L14,1,0)),IF($R14<>"",$R14,"")))) | U14: =IF(OR($S14="",$S14="Gap",$Q14=""),"",IF($Q14<Config!$C$2-Config!$C$3,"STALE","")) -> STALE | V14: =IF(OR(ISNUMBER(SEARCH("ALL",$E14)),ISNUMBER(SEARCH("ADV",$E14))),1,0) -> 0 | W14: =IF(OR(ISNUMBER(SEARCH("ALL",$E14)),ISNUMBER(SEARCH("SMF",$E14))),1,0) -> 0 | X14: =IF(OR(ISNUMBER(SEARCH("ALL",$E14)),ISNUMBER(SEARCH("MKT",$E14))),1,0) -> 0 | Y14: =IF(OR(ISNUMBER(SEARCH("ALL",$E14)),ISNUMBER(SEARCH("SCM",$E14))),1,0) -> 0 | Z14: =IF(OR(ISNUMBER(SEARCH("ALL",$E14)),ISNUMBER(SEARCH("FIN",$E14))),1,0) -> 0 | AA14: =IF(OR(ISNUMBER(SEARCH("ALL",$E14)),ISNUMBER(SEARCH("AGI",$E14))),1,0) -> 0 | AB14: ⚠ The indicator name says women who OWN land while the canonical statistic counts women agricultural holders (operators), who may rent rather than own. | AC14: HOLD
A15: 2.1 | B15: Rural mobile broadband coverage (3G/4G) | C15: C1 | D15: Foundation | E15: ALL | F15: UNIVERSAL | G15: T | H15: H | I15: 20 | J15: 40 | K15: 60 | L15: 80 | M15: DATA GAP — no rural-specific mobile broadband coverage is published for Egypt by ITU, NTRA or MCIT. Context (not scored): national population coverage at least 3G = 99.8% (ITU DataHub, 2025) | N15: Structured source search, 22 August 2026 | Q15: 2025 | S15: =IF($M15="","",IF(ISNUMBER($M15),"Measured",IF(ISNUMBER(SEARCH("DATA GAP",UPPER($M15))),"Gap",IF(AND($N15<>"",$P15<>"T5"),"Documented","Judged")))) -> Gap | T15: =IF($AC15<>"","",IF(OR($S15="",$S15="Gap"),"",IF($S15="Measured",1+IF($H15="H",IF($M15>=$I15,1,0)+IF($M15>=$J15,1,0)+IF($M15>=$K15,1,0)+IF($M15>=$L15,1,0),IF($M15<=$I15,1,0)+IF($M15<=$J15,1,0)+IF($M15<=$K15,1,0)+IF($M15<=$L15,1,0)),IF($R15<>"",$R15,"")))) | U15: =IF(OR($S15="",$S15="Gap",$Q15=""),"",IF($Q15<Config!$C$2-Config!$C$3,"STALE","")) | V15: =IF(OR(ISNUMBER(SEARCH("ALL",$E15)),ISNUMBER(SEARCH("ADV",$E15))),1,0) -> 1 | W15: =IF(OR(ISNUMBER(SEARCH("ALL",$E15)),ISNUMBER(SEARCH("SMF",$E15))),1,0) -> 1 | X15: =IF(OR(ISNUMBER(SEARCH("ALL",$E15)),ISNUMBER(SEARCH("MKT",$E15))),1,0) -> 1 | Y15: =IF(OR(ISNUMBER(SEARCH("ALL",$E15)),ISNUMBER(SEARCH("SCM",$E15))),1,0) -> 1 | Z15: =IF(OR(ISNUMBER(SEARCH("ALL",$E15)),ISNUMBER(SEARCH("FIN",$E15))),1,0) -> 1 | AA15: =IF(OR(ISNUMBER(SEARCH("ALL",$E15)),ISNUMBER(SEARCH("AGI",$E15))),1,0) -> 1 | AB15: ⚠ The name asserts RURAL coverage, but Egypt's row records the ITU national at-least-3G figure as a clean cls="Measured" number that scores level 5 mechanically, while Nigeria records a rural-but-4G-only modeled estimate — so the register's only universal connectivity prerequisite carries a…
A16: 2.4 | B16: Individuals using the Internet (%) | C16: C1 | D16: Foundation | E16: ALL | G16: T | H16: H | I16: 20 | J16: 40 | K16: 60 | L16: 80 | M16: 74.648399 | N16: World Bank WDI IT.NET.USER.ZS | O16: https://api.worldbank.org/v2/country/EGY/indicator/IT.NET.USER.ZS?format=json&mrnev=1&per_page=5 | P16: T1 | Q16: 2024 | S16: =IF($M16="","",IF(ISNUMBER($M16),"Measured",IF(ISNUMBER(SEARCH("DATA GAP",UPPER($M16))),"Gap",IF(AND($N16<>"",$P16<>"T5"),"Documented","Judged")))) -> Measured | T16: =IF($AC16<>"","",IF(OR($S16="",$S16="Gap"),"",IF($S16="Measured",1+IF($H16="H",IF($M16>=$I16,1,0)+IF($M16>=$J16,1,0)+IF($M16>=$K16,1,0)+IF($M16>=$L16,1,0),IF($M16<=$I16,1,0)+IF($M16<=$J16,1,0)+IF($M16<=$K16,1,0)+IF($M16<=$L16,1,0)),IF($R16<>"",$R16,"")))) -> 4 | U16: =IF(OR($S16="",$S16="Gap",$Q16=""),"",IF($Q16<Config!$C$2-Config!$C$3,"STALE","")) | V16: =IF(OR(ISNUMBER(SEARCH("ALL",$E16)),ISNUMBER(SEARCH("ADV",$E16))),1,0) -> 1 | W16: =IF(OR(ISNUMBER(SEARCH("ALL",$E16)),ISNUMBER(SEARCH("SMF",$E16))),1,0) -> 1 | X16: =IF(OR(ISNUMBER(SEARCH("ALL",$E16)),ISNUMBER(SEARCH("MKT",$E16))),1,0) -> 1 | Y16: =IF(OR(ISNUMBER(SEARCH("ALL",$E16)),ISNUMBER(SEARCH("SCM",$E16))),1,0) -> 1 | Z16: =IF(OR(ISNUMBER(SEARCH("ALL",$E16)),ISNUMBER(SEARCH("FIN",$E16))),1,0) -> 1 | AA16: =IF(OR(ISNUMBER(SEARCH("ALL",$E16)),ISNUMBER(SEARCH("AGI",$E16))),1,0) -> 1
A17: 2.5 | B17: Mobile broadband price (% GNI pc) | C17: C1 | D17: Foundation | E17: ALL | G17: T | H17: L | I17: 10 | J17: 5 | K17: 2 | L17: 1 | M17: 0.9 | N17: ITU DataHub — Other ICT price baskets: Data-only mobile-broadband basket (2GB) (2021-2024 definition), % of GNI p.c. — Egypt (accessed 2026-08-22) | O17: https://datahub.itu.int/data/?e=EGY&i=100123&s=34593 | P17: T1 | Q17: 2025 | S17: =IF($M17="","",IF(ISNUMBER($M17),"Measured",IF(ISNUMBER(SEARCH("DATA GAP",UPPER($M17))),"Gap",IF(AND($N17<>"",$P17<>"T5"),"Documented","Judged")))) -> Measured | T17: =IF($AC17<>"","",IF(OR($S17="",$S17="Gap"),"",IF($S17="Measured",1+IF($H17="H",IF($M17>=$I17,1,0)+IF($M17>=$J17,1,0)+IF($M17>=$K17,1,0)+IF($M17>=$L17,1,0),IF($M17<=$I17,1,0)+IF($M17<=$J17,1,0)+IF($M17<=$K17,1,0)+IF($M17<=$L17,1,0)),IF($R17<>"",$R17,"")))) -> 5 | U17: =IF(OR($S17="",$S17="Gap",$Q17=""),"",IF($Q17<Config!$C$2-Config!$C$3,"STALE","")) | V17: =IF(OR(ISNUMBER(SEARCH("ALL",$E17)),ISNUMBER(SEARCH("ADV",$E17))),1,0) -> 1 | W17: =IF(OR(ISNUMBER(SEARCH("ALL",$E17)),ISNUMBER(SEARCH("SMF",$E17))),1,0) -> 1 | X17: =IF(OR(ISNUMBER(SEARCH("ALL",$E17)),ISNUMBER(SEARCH("MKT",$E17))),1,0) -> 1 | Y17: =IF(OR(ISNUMBER(SEARCH("ALL",$E17)),ISNUMBER(SEARCH("SCM",$E17))),1,0) -> 1 | Z17: =IF(OR(ISNUMBER(SEARCH("ALL",$E17)),ISNUMBER(SEARCH("FIN",$E17))),1,0) -> 1 | AA17: =IF(OR(ISNUMBER(SEARCH("ALL",$E17)),ISNUMBER(SEARCH("AGI",$E17))),1,0) -> 1 | AB17: The name fixes neither the basket allowance (2GB vs ITU's 2025 headline 5GB), nor the basket type (data-only vs voice+data), nor whether "% GNI pc" is monthly or annual — and Egypt's value sits on a series ITU has retired to a legacy label while Nigeria's comes from the live headline series id,…
A18: 2.7 | B18: Rural smartphone ownership (%) | C18: C1 | D18: Foundation | E18: ALL | G18: T | H18: H | I18: 20 | J18: 40 | K18: 60 | L18: 80 | M18: 67.4 | N18: MCIT ICT Indicators Quarterly Bulletin, June 2022 (Q2 2022), p.6 — 'Households with Smartphone according to (Urban/Rural)', reporting the MCIT/CAPMAS 'ICT usage in household and individuals' survey 2021-2022 | O18: https://mcit.gov.eg/Upcont/Documents/Publications_2482022000_ICT_Indicators_Quarterly_Bulletin_Q2_2022_24082022.pdf | P18: T3 | Q18: 2022 | S18: =IF($M18="","",IF(ISNUMBER($M18),"Measured",IF(ISNUMBER(SEARCH("DATA GAP",UPPER($M18))),"Gap",IF(AND($N18<>"",$P18<>"T5"),"Documented","Judged")))) -> Measured | T18: =IF($AC18<>"","",IF(OR($S18="",$S18="Gap"),"",IF($S18="Measured",1+IF($H18="H",IF($M18>=$I18,1,0)+IF($M18>=$J18,1,0)+IF($M18>=$K18,1,0)+IF($M18>=$L18,1,0),IF($M18<=$I18,1,0)+IF($M18<=$J18,1,0)+IF($M18<=$K18,1,0)+IF($M18<=$L18,1,0)),IF($R18<>"",$R18,"")))) -> 4 | U18: =IF(OR($S18="",$S18="Gap",$Q18=""),"",IF($Q18<Config!$C$2-Config!$C$3,"STALE","")) -> STALE | V18: =IF(OR(ISNUMBER(SEARCH("ALL",$E18)),ISNUMBER(SEARCH("ADV",$E18))),1,0) -> 1 | W18: =IF(OR(ISNUMBER(SEARCH("ALL",$E18)),ISNUMBER(SEARCH("SMF",$E18))),1,0) -> 1 | X18: =IF(OR(ISNUMBER(SEARCH("ALL",$E18)),ISNUMBER(SEARCH("MKT",$E18))),1,0) -> 1 | Y18: =IF(OR(ISNUMBER(SEARCH("ALL",$E18)),ISNUMBER(SEARCH("SCM",$E18))),1,0) -> 1 | Z18: =IF(OR(ISNUMBER(SEARCH("ALL",$E18)),ISNUMBER(SEARCH("FIN",$E18))),1,0) -> 1 | AA18: =IF(OR(ISNUMBER(SEARCH("ALL",$E18)),ISNUMBER(SEARCH("AGI",$E18))),1,0) -> 1 | AB18: "Ownership" of a personal device implies individuals; both countries record the share of rural HOUSEHOLDS owning at least one smartphone, which reads systematically higher than the individual measure.
A19: 2.9 | B19: Rural electricity access (%) | C19: C1 | D19: Foundation | E19: ALL | F19: UNIVERSAL | G19: T | H19: H | I19: 20 | J19: 40 | K19: 60 | L19: 80 | M19: 100 | N19: World Bank WDI EG.ELC.ACCS.RU.ZS | O19: https://api.worldbank.org/v2/country/EGY/indicator/EG.ELC.ACCS.RU.ZS?format=json&mrnev=1&per_page=5 | P19: T1 | Q19: 2024 | S19: =IF($M19="","",IF(ISNUMBER($M19),"Measured",IF(ISNUMBER(SEARCH("DATA GAP",UPPER($M19))),"Gap",IF(AND($N19<>"",$P19<>"T5"),"Documented","Judged")))) -> Measured | T19: =IF($AC19<>"","",IF(OR($S19="",$S19="Gap"),"",IF($S19="Measured",1+IF($H19="H",IF($M19>=$I19,1,0)+IF($M19>=$J19,1,0)+IF($M19>=$K19,1,0)+IF($M19>=$L19,1,0),IF($M19<=$I19,1,0)+IF($M19<=$J19,1,0)+IF($M19<=$K19,1,0)+IF($M19<=$L19,1,0)),IF($R19<>"",$R19,"")))) -> 5 | U19: =IF(OR($S19="",$S19="Gap",$Q19=""),"",IF($Q19<Config!$C$2-Config!$C$3,"STALE","")) | V19: =IF(OR(ISNUMBER(SEARCH("ALL",$E19)),ISNUMBER(SEARCH("ADV",$E19))),1,0) -> 1 | W19: =IF(OR(ISNUMBER(SEARCH("ALL",$E19)),ISNUMBER(SEARCH("SMF",$E19))),1,0) -> 1 | X19: =IF(OR(ISNUMBER(SEARCH("ALL",$E19)),ISNUMBER(SEARCH("MKT",$E19))),1,0) -> 1 | Y19: =IF(OR(ISNUMBER(SEARCH("ALL",$E19)),ISNUMBER(SEARCH("SCM",$E19))),1,0) -> 1 | Z19: =IF(OR(ISNUMBER(SEARCH("ALL",$E19)),ISNUMBER(SEARCH("FIN",$E19))),1,0) -> 1 | AA19: =IF(OR(ISNUMBER(SEARCH("ALL",$E19)),ISNUMBER(SEARCH("AGI",$E19))),1,0) -> 1
A20: 2.11 | B20: Device financing/subsidy schemes | C20: C1 | D20: Foundation | E20: ALL | G20: L | M20: No government or telco device-financing/subsidy scheme targeting low-income or rural users found for Egypt (searched 2026-08-22). What exists instead: (1) commercial telco handset installments — Telecom Egypt 'WE Gold' p | N20: NTRA (tra.gov.eg) — 'Start of the installment service for fees due on mobile phones imported from abroad through consumer finance companies' (Arabic, 6 April 2026); NTRA — 'End of exceptional exemption on imported mobile phones' (21 Jan 2026) | O20: https://www.tra.gov.eg/ar/%D8%A8%D8%AF%D8%A1-%D8%AA%D8%B7%D8%A8%D9%8A%D9%82-%D8%AE%D8%AF%D9%85%D8%A9-%D8%AA%D9%82%D8%B3%D9%8A%D8%B7-%D8%A7%D9%84%D8%B1%D8%B3%D9%88%D9%85-%D8%A7%D9%84%D9%85%D8%B3%D8%AA%D8%AD%D9%82%D8%A9-%D8%B9/ | P20: T3 | Q20: 2026 | R20: 1 | S20: =IF($M20="","",IF(ISNUMBER($M20),"Measured",IF(ISNUMBER(SEARCH("DATA GAP",UPPER($M20))),"Gap",IF(AND($N20<>"",$P20<>"T5"),"Documented","Judged")))) -> Documented | T20: =IF($AC20<>"","",IF(OR($S20="",$S20="Gap"),"",IF($S20="Measured",1+IF($H20="H",IF($M20>=$I20,1,0)+IF($M20>=$J20,1,0)+IF($M20>=$K20,1,0)+IF($M20>=$L20,1,0),IF($M20<=$I20,1,0)+IF($M20<=$J20,1,0)+IF($M20<=$K20,1,0)+IF($M20<=$L20,1,0)),IF($R20<>"",$R20,"")))) -> 1 | U20: =IF(OR($S20="",$S20="Gap",$Q20=""),"",IF($Q20<Config!$C$2-Config!$C$3,"STALE","")) | V20: =IF(OR(ISNUMBER(SEARCH("ALL",$E20)),ISNUMBER(SEARCH("ADV",$E20))),1,0) -> 1 | W20: =IF(OR(ISNUMBER(SEARCH("ALL",$E20)),ISNUMBER(SEARCH("SMF",$E20))),1,0) -> 1 | X20: =IF(OR(ISNUMBER(SEARCH("ALL",$E20)),ISNUMBER(SEARCH("MKT",$E20))),1,0) -> 1 | Y20: =IF(OR(ISNUMBER(SEARCH("ALL",$E20)),ISNUMBER(SEARCH("SCM",$E20))),1,0) -> 1 | Z20: =IF(OR(ISNUMBER(SEARCH("ALL",$E20)),ISNUMBER(SEARCH("FIN",$E20))),1,0) -> 1 | AA20: =IF(OR(ISNUMBER(SEARCH("ALL",$E20)),ISNUMBER(SEARCH("AGI",$E20))),1,0) -> 1 | AB20: The ladder's name fixes neither a targeting test nor whether a subsidy is required, and the two countries applied opposite tests to the same class of evidence — commercial telco handset instalments — producing a two-rung divergence.
A21: 3.1 | B21: UN E-Government Development Index | C21: C2 | D21: Enablers | E21: AGI,ALL | G21: T | H21: H | I21: 0.2 | J21: 0.4 | K21: 0.6 | L21: 0.8 | M21: 0.6699 | N21: UN E-Government Knowledgebase — Egypt country profile (E-Government Survey 2024) | O21: https://publicadministration.un.org/egovkb/en-us/Data/Country-Information/id/53-Egypt | P21: T1 | Q21: 2024 | S21: =IF($M21="","",IF(ISNUMBER($M21),"Measured",IF(ISNUMBER(SEARCH("DATA GAP",UPPER($M21))),"Gap",IF(AND($N21<>"",$P21<>"T5"),"Documented","Judged")))) -> Measured | T21: =IF($AC21<>"","",IF(OR($S21="",$S21="Gap"),"",IF($S21="Measured",1+IF($H21="H",IF($M21>=$I21,1,0)+IF($M21>=$J21,1,0)+IF($M21>=$K21,1,0)+IF($M21>=$L21,1,0),IF($M21<=$I21,1,0)+IF($M21<=$J21,1,0)+IF($M21<=$K21,1,0)+IF($M21<=$L21,1,0)),IF($R21<>"",$R21,"")))) -> 4 | U21: =IF(OR($S21="",$S21="Gap",$Q21=""),"",IF($Q21<Config!$C$2-Config!$C$3,"STALE","")) | V21: =IF(OR(ISNUMBER(SEARCH("ALL",$E21)),ISNUMBER(SEARCH("ADV",$E21))),1,0) -> 1 | W21: =IF(OR(ISNUMBER(SEARCH("ALL",$E21)),ISNUMBER(SEARCH("SMF",$E21))),1,0) -> 1 | X21: =IF(OR(ISNUMBER(SEARCH("ALL",$E21)),ISNUMBER(SEARCH("MKT",$E21))),1,0) -> 1 | Y21: =IF(OR(ISNUMBER(SEARCH("ALL",$E21)),ISNUMBER(SEARCH("SCM",$E21))),1,0) -> 1 | Z21: =IF(OR(ISNUMBER(SEARCH("ALL",$E21)),ISNUMBER(SEARCH("FIN",$E21))),1,0) -> 1 | AA21: =IF(OR(ISNUMBER(SEARCH("ALL",$E21)),ISNUMBER(SEARCH("AGI",$E21))),1,0) -> 1
A22: 3.3 | B22: National farmer registry | C22: C2 | D22: Enablers | E22: FIN,AGI,ADV | F22: UC:FIN,AGI | G22: L | M22: National farmer registry EXISTS and is OPERATING: the MALR 'Farmer Card' (كارت الفلاح) smart-card system is the national electronic agricultural holding registry. MALR spokesperson (via SIS, 28 Mar 2026): ~5 million farm | N22: SIS (State Information Service): 'Agriculture spokesperson: continued efforts to ensure support reaches farmers through the Farmer Card' [Arabic], 28 March 2026 | O22: https://sis.gov.eg/ar/%D8%A7%D9%84%D9%85%D8%B1%D9%83%D8%B2-%D8%A7%D9%84%D8%A5%D8%B9%D9%84%D8%A7%D9%85%D9%8A/%D8%A7%D9%84%D8%A3%D8%AE%D8%A8%D8%A7%D8%B1/%D9%85%D8%AA%D8%AD%D8%AF%D8%AB-%D8%A7%D9%84%D8%B2%D8%B1%D8%A7%D8%B9%D8%A9-%D8%AC%D9%87%D9%88%D8%AF-%D9%85%D8%B3%D8%AA%D9%85%D8%B1%D8%A9-%D9%84%D8%B6%D9%85%D8%A7%D9%86-%D9%88%D8%B5%D9%88%D9%84-%D8%A7%D9%84%D8%AF%D8%B9%D9%85-%D9%84%D9%84%D9%85%D8%B2%D8%A7%D8%B1%D8%B9%D9%8A%D9%86-%D9%85%D9%86-%D8%AE%D9%84%D8%A7%D9%84-%D9%83%D8%A7%D8%B1%D8%AA-%D8%A7%D9%84%D9%81%D9%84%D8%A7%D8%AD/ | P22: T3 | Q22: 2026 | R22: 4 | S22: =IF($M22="","",IF(ISNUMBER($M22),"Measured",IF(ISNUMBER(SEARCH("DATA GAP",UPPER($M22))),"Gap",IF(AND($N22<>"",$P22<>"T5"),"Documented","Judged")))) -> Documented | T22: =IF($AC22<>"","",IF(OR($S22="",$S22="Gap"),"",IF($S22="Measured",1+IF($H22="H",IF($M22>=$I22,1,0)+IF($M22>=$J22,1,0)+IF($M22>=$K22,1,0)+IF($M22>=$L22,1,0),IF($M22<=$I22,1,0)+IF($M22<=$J22,1,0)+IF($M22<=$K22,1,0)+IF($M22<=$L22,1,0)),IF($R22<>"",$R22,"")))) -> 4 | U22: =IF(OR($S22="",$S22="Gap",$Q22=""),"",IF($Q22<Config!$C$2-Config!$C$3,"STALE","")) | V22: =IF(OR(ISNUMBER(SEARCH("ALL",$E22)),ISNUMBER(SEARCH("ADV",$E22))),1,0) -> 1 | W22: =IF(OR(ISNUMBER(SEARCH("ALL",$E22)),ISNUMBER(SEARCH("SMF",$E22))),1,0) -> 0 | X22: =IF(OR(ISNUMBER(SEARCH("ALL",$E22)),ISNUMBER(SEARCH("MKT",$E22))),1,0) -> 0 | Y22: =IF(OR(ISNUMBER(SEARCH("ALL",$E22)),ISNUMBER(SEARCH("SCM",$E22))),1,0) -> 0 | Z22: =IF(OR(ISNUMBER(SEARCH("ALL",$E22)),ISNUMBER(SEARCH("FIN",$E22))),1,0) -> 1 | AA22: =IF(OR(ISNUMBER(SEARCH("ALL",$E22)),ISNUMBER(SEARCH("AGI",$E22))),1,0) -> 1 | AB22: The name implies a register of farmers (individuals), but Egypt's record is an agricultural holding registry embedded in a subsidy smart-card scheme, whose scale figures mix four non-comparable units — cards printed, cards distributed, farmers benefiting, and holdings registered — with no…
A23: 3.4 | B23: Digital land/plot registration | C23: C2 | D23: Enablers | E23: FIN,AGI | G23: L | M23: Digital land registration is ADOPTED but not yet a comprehensive operating digital cadastre. New: Law No. 88 of 2025 (signed 18 June 2025; Official Gazette issue 24-bis, 17 June 2025) establishes a unified national elect | N23: SIS: 'President El-Sisi Signs Law Establishing National Real Estate Identification Number Database' (Law 88/2025), June 2025 | O23: https://sis.gov.eg/Story/209329/President-El--Sisi-Signs-Law-Establishing-National-Real-Estate-Identification-Number-Database?lang=en-us | P23: T3 | Q23: 2025 | R23: 3 | S23: =IF($M23="","",IF(ISNUMBER($M23),"Measured",IF(ISNUMBER(SEARCH("DATA GAP",UPPER($M23))),"Gap",IF(AND($N23<>"",$P23<>"T5"),"Documented","Judged")))) -> Documented | T23: =IF($AC23<>"","",IF(OR($S23="",$S23="Gap"),"",IF($S23="Measured",1+IF($H23="H",IF($M23>=$I23,1,0)+IF($M23>=$J23,1,0)+IF($M23>=$K23,1,0)+IF($M23>=$L23,1,0),IF($M23<=$I23,1,0)+IF($M23<=$J23,1,0)+IF($M23<=$K23,1,0)+IF($M23<=$L23,1,0)),IF($R23<>"",$R23,"")))) -> 3 | U23: =IF(OR($S23="",$S23="Gap",$Q23=""),"",IF($Q23<Config!$C$2-Config!$C$3,"STALE","")) | V23: =IF(OR(ISNUMBER(SEARCH("ALL",$E23)),ISNUMBER(SEARCH("ADV",$E23))),1,0) -> 0 | W23: =IF(OR(ISNUMBER(SEARCH("ALL",$E23)),ISNUMBER(SEARCH("SMF",$E23))),1,0) -> 0 | X23: =IF(OR(ISNUMBER(SEARCH("ALL",$E23)),ISNUMBER(SEARCH("MKT",$E23))),1,0) -> 0 | Y23: =IF(OR(ISNUMBER(SEARCH("ALL",$E23)),ISNUMBER(SEARCH("SCM",$E23))),1,0) -> 0 | Z23: =IF(OR(ISNUMBER(SEARCH("ALL",$E23)),ISNUMBER(SEARCH("FIN",$E23))),1,0) -> 1 | AA23: =IF(OR(ISNUMBER(SEARCH("ALL",$E23)),ISNUMBER(SEARCH("AGI",$E23))),1,0) -> 1 | AB23: The name reads as one object but three distinct registers are in play — legal title, a national all-property real-estate ID database, and agricultural usufruct/holding records — and Egypt's rung-3 anchor is an economy-wide real-estate identification law (urban property included) scored inside an…
A24: 3.5 | B24: Open agricultural data (machine-readable, AI-ready) | C24: C2 | D24: Enablers | E24: AGI,ADV,SMF | G24: L | M24: Open agricultural data is ADOPTED in policy but the national open-data portal is NOT yet live. Egypt's first Open Data Policy (issued by the National Council for Artificial Intelligence, 2025; prepared by MCIT; reported | N24: Open Data Policy, Arab Republic of Egypt — issued by the National Council for Artificial Intelligence, 2025 (official PDF on ai.gov.eg) | O24: https://ai.gov.eg/SynchedFiles/en/Resources/Open%20Data%20Policy.pdf | P24: T3 | Q24: 2025 | R24: 2 | S24: =IF($M24="","",IF(ISNUMBER($M24),"Measured",IF(ISNUMBER(SEARCH("DATA GAP",UPPER($M24))),"Gap",IF(AND($N24<>"",$P24<>"T5"),"Documented","Judged")))) -> Documented | T24: =IF($AC24<>"","",IF(OR($S24="",$S24="Gap"),"",IF($S24="Measured",1+IF($H24="H",IF($M24>=$I24,1,0)+IF($M24>=$J24,1,0)+IF($M24>=$K24,1,0)+IF($M24>=$L24,1,0),IF($M24<=$I24,1,0)+IF($M24<=$J24,1,0)+IF($M24<=$K24,1,0)+IF($M24<=$L24,1,0)),IF($R24<>"",$R24,"")))) -> 2 | U24: =IF(OR($S24="",$S24="Gap",$Q24=""),"",IF($Q24<Config!$C$2-Config!$C$3,"STALE","")) | V24: =IF(OR(ISNUMBER(SEARCH("ALL",$E24)),ISNUMBER(SEARCH("ADV",$E24))),1,0) -> 1 | W24: =IF(OR(ISNUMBER(SEARCH("ALL",$E24)),ISNUMBER(SEARCH("SMF",$E24))),1,0) -> 1 | X24: =IF(OR(ISNUMBER(SEARCH("ALL",$E24)),ISNUMBER(SEARCH("MKT",$E24))),1,0) -> 0 | Y24: =IF(OR(ISNUMBER(SEARCH("ALL",$E24)),ISNUMBER(SEARCH("SCM",$E24))),1,0) -> 0 | Z24: =IF(OR(ISNUMBER(SEARCH("ALL",$E24)),ISNUMBER(SEARCH("FIN",$E24))),1,0) -> 0 | AA24: =IF(OR(ISNUMBER(SEARCH("ALL",$E24)),ISNUMBER(SEARCH("AGI",$E24))),1,0) -> 1 | AB24: ⚠ The name asserts three conjoined qualifiers — open, machine-readable, AI-ready — and Nigeria scores rung 4 ('Operating with quality') on a registration-gated statistical microdata catalog that the cell's own text says is neither open nor AI-ready, while Nigeria's actual open-data portals are…
A25: 3.6 | B25: Weather/climate data infrastructure | C25: C2 | D25: Enablers | E25: ADV,SMF,AGI | G25: L | M25: Weather/climate data infrastructure is OPERATING with ag-tailored services. The Egyptian Meteorological Authority (EMA) is the operational national met service (official site www.ema.gov.eg resolves; agrometeorology is a | N25: SIS: 'Agriculture issues its recommendations to farmers on dealing with the unstable weather wave in the coming days' [Arabic] (CLAC/ARC advisory) | O25: https://sis.gov.eg/ar/%D8%A7%D9%84%D9%85%D8%B1%D9%83%D8%B2-%D8%A7%D9%84%D8%A5%D8%B9%D9%84%D8%A7%D9%85%D9%8A/%D8%A7%D9%84%D8%A3%D8%AE%D8%A8%D8%A7%D8%B1/%D8%A7%D9%84%D8%B2%D8%B1%D8%A7%D8%B9%D8%A9-%D8%AA%D8%B5%D8%AF%D8%B1-%D8%AA%D9%88%D8%B5%D9%8A%D8%A7%D8%AA%D9%87%D8%A7-%D9%84%D9%84%D9%85%D8%B2%D8%A7%D8%B1%D8%B9%D9%8A%D9%86-%D9%81%D9%8A-%D9%83%D9%8A%D9%81%D9%8A%D8%A9-%D8%A7%D9%84%D8%AA%D8%B9%D8%A7%D9%85%D9%84-%D9%85%D8%B9-%D9%85%D9%88%D8%AC%D8%A9-%D8%A7%D9%84%D8%B7%D9%82%D8%B3-%D8%BA%D9%8A%D8%B1-%D9%85%D8%B3%D8%AA%D9%82%D8%B1%D8%A9-%D8%AE%D9%84%D8%A7%D9%84-%D8%A7%D9%84%D8%A3%D9%8A%D8%A7%D9%85-%D8%A7%D9%84%D9%82%D8%A7%D8%AF%D9%85%D8%A9/ | P25: T3 | Q25: 2026 | R25: 4 | S25: =IF($M25="","",IF(ISNUMBER($M25),"Measured",IF(ISNUMBER(SEARCH("DATA GAP",UPPER($M25))),"Gap",IF(AND($N25<>"",$P25<>"T5"),"Documented","Judged")))) -> Documented | T25: =IF($AC25<>"","",IF(OR($S25="",$S25="Gap"),"",IF($S25="Measured",1+IF($H25="H",IF($M25>=$I25,1,0)+IF($M25>=$J25,1,0)+IF($M25>=$K25,1,0)+IF($M25>=$L25,1,0),IF($M25<=$I25,1,0)+IF($M25<=$J25,1,0)+IF($M25<=$K25,1,0)+IF($M25<=$L25,1,0)),IF($R25<>"",$R25,"")))) -> 4 | U25: =IF(OR($S25="",$S25="Gap",$Q25=""),"",IF($Q25<Config!$C$2-Config!$C$3,"STALE","")) | V25: =IF(OR(ISNUMBER(SEARCH("ALL",$E25)),ISNUMBER(SEARCH("ADV",$E25))),1,0) -> 1 | W25: =IF(OR(ISNUMBER(SEARCH("ALL",$E25)),ISNUMBER(SEARCH("SMF",$E25))),1,0) -> 1 | X25: =IF(OR(ISNUMBER(SEARCH("ALL",$E25)),ISNUMBER(SEARCH("MKT",$E25))),1,0) -> 0 | Y25: =IF(OR(ISNUMBER(SEARCH("ALL",$E25)),ISNUMBER(SEARCH("SCM",$E25))),1,0) -> 0 | Z25: =IF(OR(ISNUMBER(SEARCH("ALL",$E25)),ISNUMBER(SEARCH("FIN",$E25))),1,0) -> 0 | AA25: =IF(OR(ISNUMBER(SEARCH("ALL",$E25)),ISNUMBER(SEARCH("AGI",$E25))),1,0) -> 1 | AB25: The name is data infrastructure — observation networks, archives, data access — but both countries are scored at rung 4 on advisory products issued to farmers, with no station density, archive, API or data-access evidence recorded on either row, and the advisory content overlaps indicator 8.17…
A26: 3.7 | B26: Satellite/EO data integration | C26: C2 | D26: Enablers | E26: AGI,SMF | G26: L | M26: Satellite/EO integration in agriculture is OPERATING beyond pilots. T3 (MALR press conference, 6 Dec 2021): MALR and MCIT used AI to inventory the cropped area of each crop on the ground ('completed the summer-season cro | N26: MALR: 'Ministers of Agriculture and Communications announce pilot launch of digital transformation services in the agricultural sector' [Arabic], 6 December 2021 (includes completed AI crop-area inventory) | O26: https://moa.gov.eg/highlights/%D8%AE%D8%AF%D9%85%D8%A7%D8%AA-%D8%A7%D9%84%D8%AA%D8%AD%D9%88%D9%84-%D8%A7%D9%84%D8%B1%D9%82%D9%85%D9%89/ | P26: T3 | Q26: 2024 | R26: 4 | S26: =IF($M26="","",IF(ISNUMBER($M26),"Measured",IF(ISNUMBER(SEARCH("DATA GAP",UPPER($M26))),"Gap",IF(AND($N26<>"",$P26<>"T5"),"Documented","Judged")))) -> Documented | T26: =IF($AC26<>"","",IF(OR($S26="",$S26="Gap"),"",IF($S26="Measured",1+IF($H26="H",IF($M26>=$I26,1,0)+IF($M26>=$J26,1,0)+IF($M26>=$K26,1,0)+IF($M26>=$L26,1,0),IF($M26<=$I26,1,0)+IF($M26<=$J26,1,0)+IF($M26<=$K26,1,0)+IF($M26<=$L26,1,0)),IF($R26<>"",$R26,"")))) -> 4 | U26: =IF(OR($S26="",$S26="Gap",$Q26=""),"",IF($Q26<Config!$C$2-Config!$C$3,"STALE","")) | V26: =IF(OR(ISNUMBER(SEARCH("ALL",$E26)),ISNUMBER(SEARCH("ADV",$E26))),1,0) -> 0 | W26: =IF(OR(ISNUMBER(SEARCH("ALL",$E26)),ISNUMBER(SEARCH("SMF",$E26))),1,0) -> 1 | X26: =IF(OR(ISNUMBER(SEARCH("ALL",$E26)),ISNUMBER(SEARCH("MKT",$E26))),1,0) -> 0 | Y26: =IF(OR(ISNUMBER(SEARCH("ALL",$E26)),ISNUMBER(SEARCH("SCM",$E26))),1,0) -> 0 | Z26: =IF(OR(ISNUMBER(SEARCH("ALL",$E26)),ISNUMBER(SEARCH("FIN",$E26))),1,0) -> 0 | AA26: =IF(OR(ISNUMBER(SEARCH("ALL",$E26)),ISNUMBER(SEARCH("AGI",$E26))),1,0) -> 1 | AB26: The name fixes neither the object nor the bar for 'integration' — Egypt is scored rung 4 on producing national crop maps, Nigeria rung 3 on institutional arrangements — and Egypt's 'operating beyond pilots' assertion rests on a source whose own title announces a pilot launch, recorded under year…
A27: 3.8 | B27: National soil map/database | C27: C2 | D27: Enablers | E27: ADV,SMF | G27: L | M27: No operating national digital soil map/database service found — best-verified status is ABSENT for a public national digital soil information service, with legacy and research assets: FAO Soils Portal hosts legacy (digit | N27: FAO Soils Portal — Regional and National Soil Maps and Databases (Egypt legacy maps) | O27: https://www.fao.org/soils-portal/data-hub/soil-maps-and-databases/regional-and-national-soil-maps-and-databases/en/ | P27: T1 | Q27: 2026 | R27: 1 | S27: =IF($M27="","",IF(ISNUMBER($M27),"Measured",IF(ISNUMBER(SEARCH("DATA GAP",UPPER($M27))),"Gap",IF(AND($N27<>"",$P27<>"T5"),"Documented","Judged")))) -> Documented | T27: =IF($AC27<>"","",IF(OR($S27="",$S27="Gap"),"",IF($S27="Measured",1+IF($H27="H",IF($M27>=$I27,1,0)+IF($M27>=$J27,1,0)+IF($M27>=$K27,1,0)+IF($M27>=$L27,1,0),IF($M27<=$I27,1,0)+IF($M27<=$J27,1,0)+IF($M27<=$K27,1,0)+IF($M27<=$L27,1,0)),IF($R27<>"",$R27,"")))) -> 1 | U27: =IF(OR($S27="",$S27="Gap",$Q27=""),"",IF($Q27<Config!$C$2-Config!$C$3,"STALE","")) | V27: =IF(OR(ISNUMBER(SEARCH("ALL",$E27)),ISNUMBER(SEARCH("ADV",$E27))),1,0) -> 1 | W27: =IF(OR(ISNUMBER(SEARCH("ALL",$E27)),ISNUMBER(SEARCH("SMF",$E27))),1,0) -> 1 | X27: =IF(OR(ISNUMBER(SEARCH("ALL",$E27)),ISNUMBER(SEARCH("MKT",$E27))),1,0) -> 0 | Y27: =IF(OR(ISNUMBER(SEARCH("ALL",$E27)),ISNUMBER(SEARCH("SCM",$E27))),1,0) -> 0 | Z27: =IF(OR(ISNUMBER(SEARCH("ALL",$E27)),ISNUMBER(SEARCH("FIN",$E27))),1,0) -> 0 | AA27: =IF(OR(ISNUMBER(SEARCH("ALL",$E27)),ISNUMBER(SEARCH("AGI",$E27))),1,0) -> 0 | AB27: Does a digitized legacy paper soil map satisfy the indicator, or does the ladder measure an operating digital soil information service?
A28: 3.11 | B28: Agricultural data interoperability standards | C28: C2 | D28: Enablers | E28: AGI,ALL | F28: UC:AGI | G28: L | M28: No published agricultural data interoperability standards/schemas found for Egypt — ABSENT after active refutation attempt. Nearest instruments, none ag-specific: (1) Open Data Policy (NCAI, 2025, T3) mandates cross-gove | N28: Open Data Policy, Arab Republic of Egypt (NCAI, 2025) — closest instrument; no ag-specific standard exists | O28: https://ai.gov.eg/SynchedFiles/en/Resources/Open%20Data%20Policy.pdf | P28: T3 | Q28: 2026 | R28: 1 | S28: =IF($M28="","",IF(ISNUMBER($M28),"Measured",IF(ISNUMBER(SEARCH("DATA GAP",UPPER($M28))),"Gap",IF(AND($N28<>"",$P28<>"T5"),"Documented","Judged")))) -> Documented | T28: =IF($AC28<>"","",IF(OR($S28="",$S28="Gap"),"",IF($S28="Measured",1+IF($H28="H",IF($M28>=$I28,1,0)+IF($M28>=$J28,1,0)+IF($M28>=$K28,1,0)+IF($M28>=$L28,1,0),IF($M28<=$I28,1,0)+IF($M28<=$J28,1,0)+IF($M28<=$K28,1,0)+IF($M28<=$L28,1,0)),IF($R28<>"",$R28,"")))) -> 1 | U28: =IF(OR($S28="",$S28="Gap",$Q28=""),"",IF($Q28<Config!$C$2-Config!$C$3,"STALE","")) | V28: =IF(OR(ISNUMBER(SEARCH("ALL",$E28)),ISNUMBER(SEARCH("ADV",$E28))),1,0) -> 1 | W28: =IF(OR(ISNUMBER(SEARCH("ALL",$E28)),ISNUMBER(SEARCH("SMF",$E28))),1,0) -> 1 | X28: =IF(OR(ISNUMBER(SEARCH("ALL",$E28)),ISNUMBER(SEARCH("MKT",$E28))),1,0) -> 1 | Y28: =IF(OR(ISNUMBER(SEARCH("ALL",$E28)),ISNUMBER(SEARCH("SCM",$E28))),1,0) -> 1 | Z28: =IF(OR(ISNUMBER(SEARCH("ALL",$E28)),ISNUMBER(SEARCH("FIN",$E28))),1,0) -> 1 | AA28: =IF(OR(ISNUMBER(SEARCH("ALL",$E28)),ISNUMBER(SEARCH("AGI",$E28))),1,0) -> 1 | AB28: Must the standard be agriculture-specific, or do cross-government open-data/DPI instruments and draft harmonisation work count as Present/Announced for this prerequisite cell?
A29: 4.1 | B29: Data protection/privacy law | C29: C3 | D29: Enablers | E29: ALL | F29: UNIVERSAL | G29: L | M29: Personal Data Protection Law No. 151/2020 in force since October 2020; Executive Regulations issued by Decree No. 816/2025 of the Minister of Communications and Information Technology on 1 November 2025, published in the | N29: Shalakany Law Office, "New Executive Regulations for Egypt's Personal Data Protection Law" (Dec 2025) — full-text analysis of Decree 816/2025 | O29: https://shalakany.com/wp-content/uploads/2025/12/New-Executive-Regulations-for-Egypts-Personal-Data-Protection-Law-.pdf | P29: T4 | Q29: 2025 | R29: 3 | S29: =IF($M29="","",IF(ISNUMBER($M29),"Measured",IF(ISNUMBER(SEARCH("DATA GAP",UPPER($M29))),"Gap",IF(AND($N29<>"",$P29<>"T5"),"Documented","Judged")))) -> Documented | T29: =IF($AC29<>"","",IF(OR($S29="",$S29="Gap"),"",IF($S29="Measured",1+IF($H29="H",IF($M29>=$I29,1,0)+IF($M29>=$J29,1,0)+IF($M29>=$K29,1,0)+IF($M29>=$L29,1,0),IF($M29<=$I29,1,0)+IF($M29<=$J29,1,0)+IF($M29<=$K29,1,0)+IF($M29<=$L29,1,0)),IF($R29<>"",$R29,"")))) -> 3 | U29: =IF(OR($S29="",$S29="Gap",$Q29=""),"",IF($Q29<Config!$C$2-Config!$C$3,"STALE","")) | V29: =IF(OR(ISNUMBER(SEARCH("ALL",$E29)),ISNUMBER(SEARCH("ADV",$E29))),1,0) -> 1 | W29: =IF(OR(ISNUMBER(SEARCH("ALL",$E29)),ISNUMBER(SEARCH("SMF",$E29))),1,0) -> 1 | X29: =IF(OR(ISNUMBER(SEARCH("ALL",$E29)),ISNUMBER(SEARCH("MKT",$E29))),1,0) -> 1 | Y29: =IF(OR(ISNUMBER(SEARCH("ALL",$E29)),ISNUMBER(SEARCH("SCM",$E29))),1,0) -> 1 | Z29: =IF(OR(ISNUMBER(SEARCH("ALL",$E29)),ISNUMBER(SEARCH("FIN",$E29))),1,0) -> 1 | AA29: =IF(OR(ISNUMBER(SEARCH("ALL",$E29)),ISNUMBER(SEARCH("AGI",$E29))),1,0) -> 1
A30: 4.2 | B30: Cybersecurity framework (ITU GCI) | C30: C3 | D30: Enablers | E30: ALL | G30: T | H30: H | I30: 0.2 | J30: 0.4 | K30: 0.6 | L30: 0.8 | M30: 100 | N30: ITU Global Cybersecurity Index 2024 (5th edition) — Egypt in Tier 1 'Role-modelling' (score band 95-100); exact score 100/100 per NTRA announcement | O30: https://www.itu.int/dms_pub/itu-d/opb/hdb/D-HDB-GCI.01-2024-PDF-E.pdf | P30: T1 | Q30: 2024 | S30: =IF($M30="","",IF(ISNUMBER($M30),"Measured",IF(ISNUMBER(SEARCH("DATA GAP",UPPER($M30))),"Gap",IF(AND($N30<>"",$P30<>"T5"),"Documented","Judged")))) -> Measured | T30: =IF($AC30<>"","",IF(OR($S30="",$S30="Gap"),"",IF($S30="Measured",1+IF($H30="H",IF($M30>=$I30,1,0)+IF($M30>=$J30,1,0)+IF($M30>=$K30,1,0)+IF($M30>=$L30,1,0),IF($M30<=$I30,1,0)+IF($M30<=$J30,1,0)+IF($M30<=$K30,1,0)+IF($M30<=$L30,1,0)),IF($R30<>"",$R30,"")))) -> 5 | U30: =IF(OR($S30="",$S30="Gap",$Q30=""),"",IF($Q30<Config!$C$2-Config!$C$3,"STALE","")) | V30: =IF(OR(ISNUMBER(SEARCH("ALL",$E30)),ISNUMBER(SEARCH("ADV",$E30))),1,0) -> 1 | W30: =IF(OR(ISNUMBER(SEARCH("ALL",$E30)),ISNUMBER(SEARCH("SMF",$E30))),1,0) -> 1 | X30: =IF(OR(ISNUMBER(SEARCH("ALL",$E30)),ISNUMBER(SEARCH("MKT",$E30))),1,0) -> 1 | Y30: =IF(OR(ISNUMBER(SEARCH("ALL",$E30)),ISNUMBER(SEARCH("SCM",$E30))),1,0) -> 1 | Z30: =IF(OR(ISNUMBER(SEARCH("ALL",$E30)),ISNUMBER(SEARCH("FIN",$E30))),1,0) -> 1 | AA30: =IF(OR(ISNUMBER(SEARCH("ALL",$E30)),ISNUMBER(SEARCH("AGI",$E30))),1,0) -> 1 | AB30: Thresholds are defined on a 0–1 basis but Egypt is recorded as 100 and Nigeria as 0.824, so the same register column holds two incommensurable scales; separately, neither number is an overall score ITU actually publishes in the GCI 2024 report.
A31: 4.3 | B31: Government AI Readiness Index | C31: C3 | D31: Enablers | E31: AGI,ALL | G31: T | H31: H | I31: 20 | J31: 40 | K31: 60 | L31: 80 | M31: 55.63 | N31: Oxford Insights Government AI Readiness Index 2024 — Full rankings annex: Egypt total 55.63 (Government 68.98, Technology Sector 42.13, Data & Infrastructure 55.77) | O31: https://oxfordinsights.com/wp-content/uploads/2024/12/2024-Government-AI-Readiness-Index.pdf | P31: T4 | Q31: 2024 | S31: =IF($M31="","",IF(ISNUMBER($M31),"Measured",IF(ISNUMBER(SEARCH("DATA GAP",UPPER($M31))),"Gap",IF(AND($N31<>"",$P31<>"T5"),"Documented","Judged")))) -> Measured | T31: =IF($AC31<>"","",IF(OR($S31="",$S31="Gap"),"",IF($S31="Measured",1+IF($H31="H",IF($M31>=$I31,1,0)+IF($M31>=$J31,1,0)+IF($M31>=$K31,1,0)+IF($M31>=$L31,1,0),IF($M31<=$I31,1,0)+IF($M31<=$J31,1,0)+IF($M31<=$K31,1,0)+IF($M31<=$L31,1,0)),IF($R31<>"",$R31,"")))) -> 3 | U31: =IF(OR($S31="",$S31="Gap",$Q31=""),"",IF($Q31<Config!$C$2-Config!$C$3,"STALE","")) | V31: =IF(OR(ISNUMBER(SEARCH("ALL",$E31)),ISNUMBER(SEARCH("ADV",$E31))),1,0) -> 1 | W31: =IF(OR(ISNUMBER(SEARCH("ALL",$E31)),ISNUMBER(SEARCH("SMF",$E31))),1,0) -> 1 | X31: =IF(OR(ISNUMBER(SEARCH("ALL",$E31)),ISNUMBER(SEARCH("MKT",$E31))),1,0) -> 1 | Y31: =IF(OR(ISNUMBER(SEARCH("ALL",$E31)),ISNUMBER(SEARCH("SCM",$E31))),1,0) -> 1 | Z31: =IF(OR(ISNUMBER(SEARCH("ALL",$E31)),ISNUMBER(SEARCH("FIN",$E31))),1,0) -> 1 | AA31: =IF(OR(ISNUMBER(SEARCH("ALL",$E31)),ISNUMBER(SEARCH("AGI",$E31))),1,0) -> 1 | AB31: Now that the 2025 edition dropped the open overall score, does the cell score the stale 2024 overall score, substitute rank plus pillar scores, or gap?
A32: 4.4 | B32: National digital agriculture strategy | C32: C3 | D32: Enablers | E32: ALL | G32: L | M32: No dedicated national digital agriculture strategy identified as of August 2026. Digital agriculture exists as components inside broader frameworks: (a) the updated Sustainable Agricultural Development Strategy (SADS 203 | N32: MCIT press release, 'ICT Minister, Agriculture Minister follow up on joint digital transformation projects', 9 June 2021 | O32: https://mcit.gov.eg/en/Media_Center/Press_Room/Press_Releases/63422 | P32: T3 | Q32: 2021 | R32: 1 | S32: =IF($M32="","",IF(ISNUMBER($M32),"Measured",IF(ISNUMBER(SEARCH("DATA GAP",UPPER($M32))),"Gap",IF(AND($N32<>"",$P32<>"T5"),"Documented","Judged")))) -> Documented | T32: =IF($AC32<>"","",IF(OR($S32="",$S32="Gap"),"",IF($S32="Measured",1+IF($H32="H",IF($M32>=$I32,1,0)+IF($M32>=$J32,1,0)+IF($M32>=$K32,1,0)+IF($M32>=$L32,1,0),IF($M32<=$I32,1,0)+IF($M32<=$J32,1,0)+IF($M32<=$K32,1,0)+IF($M32<=$L32,1,0)),IF($R32<>"",$R32,"")))) -> 1 | U32: =IF(OR($S32="",$S32="Gap",$Q32=""),"",IF($Q32<Config!$C$2-Config!$C$3,"STALE","")) -> STALE | V32: =IF(OR(ISNUMBER(SEARCH("ALL",$E32)),ISNUMBER(SEARCH("ADV",$E32))),1,0) -> 1 | W32: =IF(OR(ISNUMBER(SEARCH("ALL",$E32)),ISNUMBER(SEARCH("SMF",$E32))),1,0) -> 1 | X32: =IF(OR(ISNUMBER(SEARCH("ALL",$E32)),ISNUMBER(SEARCH("MKT",$E32))),1,0) -> 1 | Y32: =IF(OR(ISNUMBER(SEARCH("ALL",$E32)),ISNUMBER(SEARCH("SCM",$E32))),1,0) -> 1 | Z32: =IF(OR(ISNUMBER(SEARCH("ALL",$E32)),ISNUMBER(SEARCH("FIN",$E32))),1,0) -> 1 | AA32: =IF(OR(ISNUMBER(SEARCH("ALL",$E32)),ISNUMBER(SEARCH("AGI",$E32))),1,0) -> 1 | AB32: Does the indicator score only a dedicated digital-agriculture strategy document, or does it credit digital-ag components embedded in broader national strategies and active programmes running without a strategy?
A33: 4.5 | B33: Agricultural data governance framework | C33: C3 | D33: Enablers | E33: AGI,FIN | F33: UC:AGI | G33: L | M33: No agricultural data governance framework (sector-specific rules on agricultural data sharing, ownership or use) identified — refutation attempt failed. The general PDPL 151/2020 and its Executive Regulations (Decree 816 | N33: OECD, Policies for the Future of Farming and Food in Egypt (agricultural policy review — no agricultural data governance instrument appears) | O33: https://www.oecd.org/en/publications/policies-for-the-future-of-farming-and-food-in-egypt_cab0cefd-en/full-report/trends-and-evaluation-of-agricultural-policy-in-egypt_416e1bd0.html | P33: T2 | Q33: 2026 | R33: 1 | S33: =IF($M33="","",IF(ISNUMBER($M33),"Measured",IF(ISNUMBER(SEARCH("DATA GAP",UPPER($M33))),"Gap",IF(AND($N33<>"",$P33<>"T5"),"Documented","Judged")))) -> Documented | T33: =IF($AC33<>"","",IF(OR($S33="",$S33="Gap"),"",IF($S33="Measured",1+IF($H33="H",IF($M33>=$I33,1,0)+IF($M33>=$J33,1,0)+IF($M33>=$K33,1,0)+IF($M33>=$L33,1,0),IF($M33<=$I33,1,0)+IF($M33<=$J33,1,0)+IF($M33<=$K33,1,0)+IF($M33<=$L33,1,0)),IF($R33<>"",$R33,"")))) -> 1 | U33: =IF(OR($S33="",$S33="Gap",$Q33=""),"",IF($Q33<Config!$C$2-Config!$C$3,"STALE","")) | V33: =IF(OR(ISNUMBER(SEARCH("ALL",$E33)),ISNUMBER(SEARCH("ADV",$E33))),1,0) -> 0 | W33: =IF(OR(ISNUMBER(SEARCH("ALL",$E33)),ISNUMBER(SEARCH("SMF",$E33))),1,0) -> 0 | X33: =IF(OR(ISNUMBER(SEARCH("ALL",$E33)),ISNUMBER(SEARCH("MKT",$E33))),1,0) -> 0 | Y33: =IF(OR(ISNUMBER(SEARCH("ALL",$E33)),ISNUMBER(SEARCH("SCM",$E33))),1,0) -> 0 | Z33: =IF(OR(ISNUMBER(SEARCH("ALL",$E33)),ISNUMBER(SEARCH("FIN",$E33))),1,0) -> 1 | AA33: =IF(OR(ISNUMBER(SEARCH("ALL",$E33)),ISNUMBER(SEARCH("AGI",$E33))),1,0) -> 1
A34: 4.6 | B34: National AI strategy with agriculture component | C34: C3 | D34: Enablers | E34: AGI,ALL | G34: L | M34: Egypt National AI Strategy, 2nd edition (2025-2030), unveiled January 2025 (1st edition 2021), explicitly includes agriculture: named among strategic sectors for AI integration ('agriculture, manufacturing, defense, educ | N34: Egypt National Artificial Intelligence Strategy, Second Edition 2025-2030 (official English text, ai.gov.eg, 16 Jan 2025) | O34: https://ai.gov.eg/SynchedFiles/en/Resources/AIstrategy%20English%2016-1-2025-1.pdf | P34: T3 | Q34: 2025 | R34: 4 | S34: =IF($M34="","",IF(ISNUMBER($M34),"Measured",IF(ISNUMBER(SEARCH("DATA GAP",UPPER($M34))),"Gap",IF(AND($N34<>"",$P34<>"T5"),"Documented","Judged")))) -> Documented | T34: =IF($AC34<>"","",IF(OR($S34="",$S34="Gap"),"",IF($S34="Measured",1+IF($H34="H",IF($M34>=$I34,1,0)+IF($M34>=$J34,1,0)+IF($M34>=$K34,1,0)+IF($M34>=$L34,1,0),IF($M34<=$I34,1,0)+IF($M34<=$J34,1,0)+IF($M34<=$K34,1,0)+IF($M34<=$L34,1,0)),IF($R34<>"",$R34,"")))) -> 4 | U34: =IF(OR($S34="",$S34="Gap",$Q34=""),"",IF($Q34<Config!$C$2-Config!$C$3,"STALE","")) | V34: =IF(OR(ISNUMBER(SEARCH("ALL",$E34)),ISNUMBER(SEARCH("ADV",$E34))),1,0) -> 1 | W34: =IF(OR(ISNUMBER(SEARCH("ALL",$E34)),ISNUMBER(SEARCH("SMF",$E34))),1,0) -> 1 | X34: =IF(OR(ISNUMBER(SEARCH("ALL",$E34)),ISNUMBER(SEARCH("MKT",$E34))),1,0) -> 1 | Y34: =IF(OR(ISNUMBER(SEARCH("ALL",$E34)),ISNUMBER(SEARCH("SCM",$E34))),1,0) -> 1 | Z34: =IF(OR(ISNUMBER(SEARCH("ALL",$E34)),ISNUMBER(SEARCH("FIN",$E34))),1,0) -> 1 | AA34: =IF(OR(ISNUMBER(SEARCH("ALL",$E34)),ISNUMBER(SEARCH("AGI",$E34))),1,0) -> 1 | AB34: What evidence makes a strategy 'Adopted' — official publication, or formal executive/cabinet approval?
