Workbook
Name BandL1_from: Config!$D$7
Name BandL2_from: Config!$D$8
Name BandL3_from: Config!$D$9
Name BandL4_from: Config!$D$10
Name BandL5_from: Config!$D$11
Name BandL5_to: Config!$E$11
Name Conf_High: Config!$C$47
Name Conf_Low: Config!$C$49
Name Conf_Medium: Config!$C$48
Name Cov_CMS: Config!$C$18
Name Cov_EMS: Config!$C$19
Name Cov_Pillar: Config!$C$17
Name Ev_Min: Config!$C$20
Name Leapfrog_Gap: Config!$C$30
Name Pillars: Config!$B$34:$B$41
Name Roles: Config!$C$34:$C$41
Name Stage2_CMS: Config!$C$21
Name Stage3_CMS: Config!$C$22
Name Stage3_EMS: Config!$C$23
Name Stage4_CMS: Config!$C$24
Name Stage4_EMS: Config!$C$25
Name Stage4_OES: Config!$C$26
Name Stage5_CMS: Config!$C$27
Name Stage5_EMS: Config!$C$28
Name Stage5_OES: Config!$C$29
Name Weights: Config!$D$34:$D$41

Sheet Read Me
B2: DAMM v1.4 — Live Scoring Workbook
B3: Digital Agriculture Maturity Model · 102 indicators · 8 pillars · CMS / EMS / OES
B5: What this workbook is
B7: Purpose | C7: A structured diagnostic for scoring a country's digital-agriculture readiness. Feeds a Digital Agriculture Roadmap (DAR); does NOT replace professional judgement.
B8: What v1.4 adds vs v1.3 | C8: v1.3 was a config file for an external app. v1.4 restores live scoring in Excel: every pillar score, read-out, stage, coverage figure and gate flag is a formula, recomputed as you edit.
B9: Three read-outs, never one number | C9: Capability (CMS), Ecosystem (EMS) and Outcomes (OES) are reported separately and never averaged. A country can build strong systems before outcomes move; a composite would hide that.
B10: Foundations are not tradeable | C10: 14 core-gate indicators are prerequisites. A core gate at Level 1 caps the overall stage at Stage 1. An unmeasured core gate suppresses the stage entirely.
B11: Silence beats a confident guess | C11: Below its coverage gate (60% pillar / 70% CMS / 60% EMS) a pillar reads Not rated. An unmeasured core gate suppresses the stage.
B12: Confidence & staleness | C12: Every reading carries a High/Medium/Low confidence and an observation year. Readings past their max-age limit are flagged Stale.
B13: Nothing before the mandate is an assessment | C13: Everything assembled before a government mandate is an ENGAGEMENT PACKAGE, not an assessment. No stage is claimable until human validation.
B14: Prohibitions wired in | C14: No cross-country ranking. No stage as PDO/DLI/disbursement condition. No automatic financing or vendor decisions. No stage without human validation.
B16: How to use this workbook
B18: 1. Study Egypt worked example | C18: Open 'Egypt (worked)' to see how a country is populated. Note the Level column (D), Confidence (F), Year (G), Source (H).
B19: 2. Duplicate the Blank Template | C19: Right-click the 'Blank Template' tab → Move or Copy → tick Create a Copy. Rename to your country.
B20: 3. Populate columns C–H | C20: For each row: enter the observed Value, the assessor Level 1–5 (which always wins over the machine suggestion), Confidence H/M/L, Observation Year, Source name and URL. Leave Level blank to mark a Data Gap.
B21: 4. Read the 'Scores' tab | C21: The dashboard reads live from your populated sheet. Change the country reference in Config!D6 to point at your new sheet.
B22: 5. Check gate flags | C22: The Scores sheet flags any core gate at L1, any unmeasured core gate, any pillar below coverage, and any stale readings. Address these before claiming a stage.
B23: 6. Export for the panel | C23: Filter Indicators sheet for panel scoring. Record dissent on anchored rubrics in the Notes column.
B25: Sheet index
B27: Scores | C27: Live dashboard: pillar / CMS / EMS / OES / stage / coverage / core-gate status / staleness
B28: Egypt (worked) | C28: Full worked example populated with Egypt data — 102 rows, live formulas
B29: Blank Template | C29: Empty scoring workbook — duplicate and rename for a new country
B30: Indicators | C30: 102-indicator census: pillar, role, method, direction, core gate, max age, thresholds
B31: Level Anchors | C31: Written L1–L5 anchor text for anchored rubric indicators
B32: Core Gates | C32: The 14 prerequisite indicators and why they gate
B33: Config | C33: Single source of truth: bands, coverage gates, weights, confidence weights, staleness limits
B34: Decision Ladder | C34: 8 steps from automated diagnostic (T0) to adoption (D6), with named decider
B35: Glossary | C35: CMS, EMS, OES, core gates, coverage, provisional, stale, engagement package
B36: Methodology | C36: Rules, cascade, provenance, prohibitions
B37: Changelog | C37: v1.0 → v1.1 → v1.3 → v1.4

Sheet Scores
B2: Scores — live dashboard
B3: Reads 'Egypt (worked)'. To point at a different country, copy this sheet and Find/Replace the tab name.
B5: Pillar scores
B6: Pillar | C6: Name | D6: Role | E6: # indicators | F6: # levelled | G6: Coverage | H6: Mean level | I6: Band | J6: Status
B7: C0 | C7: Agricultural context & need | D7: Context | E7: =COUNTIF('Egypt (worked)'!$D$8:$D$109,"C0") -> 8 | F7: =SUMPRODUCT(('Egypt (worked)'!$D$8:$D$109="C0")*ISNUMBER('Egypt (worked)'!$L$8:$L$109)) -> 0 | G7: =IF(E7=0,0,F7/E7) -> 0 | H7: ="—" -> — | I7: ="Context (never scored)" -> Context (never scored) | J7: =""
B8: C1 | C8: Connectivity & affordable access | D8: Capability | E8: =COUNTIF('Egypt (worked)'!$D$8:$D$109,"C1") -> 11 | F8: =SUMPRODUCT(('Egypt (worked)'!$D$8:$D$109="C1")*ISNUMBER('Egypt (worked)'!$L$8:$L$109)) -> 11 | G8: =IF(E8=0,0,F8/E8) -> 1 | H8: =IF(G8<Cov_Pillar,"Not rated",IF(F8=0,"Not rated",AVERAGEIFS('Egypt (worked)'!$L$8:$L$109,'Egypt (worked)'!$D$8:$D$109,"C1"))) -> 3.8181818 | I8: =IF(NOT(ISNUMBER(H8)),H8,IF(H8<BandL2_from,"Nascent",IF(H8<BandL3_from,"Emerging",IF(H8<BandL4_from,"Established",IF(H8<BandL5_from,"Advanced","Transformative"))))) -> Advanced | J8: =IF(G8<Cov_Pillar,"⚑ COVERAGE",IF(SUMPRODUCT(('Egypt (worked)'!$D$8:$D$109="C1")*('Egypt (worked)'!$O$8:$O$109="STALE"))>0,"⚑ Stale evidence","")) -> ⚑ Stale evidence
B9: C2 | C9: Data infrastructure & DPI | D9: Capability | E9: =COUNTIF('Egypt (worked)'!$D$8:$D$109,"C2") -> 13 | F9: =SUMPRODUCT(('Egypt (worked)'!$D$8:$D$109="C2")*ISNUMBER('Egypt (worked)'!$L$8:$L$109)) -> 13 | G9: =IF(E9=0,0,F9/E9) -> 1 | H9: =IF(G9<Cov_Pillar,"Not rated",IF(F9=0,"Not rated",AVERAGEIFS('Egypt (worked)'!$L$8:$L$109,'Egypt (worked)'!$D$8:$D$109,"C2"))) -> 2.7692308 | I9: =IF(NOT(ISNUMBER(H9)),H9,IF(H9<BandL2_from,"Nascent",IF(H9<BandL3_from,"Emerging",IF(H9<BandL4_from,"Established",IF(H9<BandL5_from,"Advanced","Transformative"))))) -> Established | J9: =IF(G9<Cov_Pillar,"⚑ COVERAGE",IF(SUMPRODUCT(('Egypt (worked)'!$D$8:$D$109="C2")*('Egypt (worked)'!$O$8:$O$109="STALE"))>0,"⚑ Stale evidence",""))
B10: C3 | C10: Policy, governance & safeguards | D10: Capability | E10: =COUNTIF('Egypt (worked)'!$D$8:$D$109,"C3") -> 13 | F10: =SUMPRODUCT(('Egypt (worked)'!$D$8:$D$109="C3")*ISNUMBER('Egypt (worked)'!$L$8:$L$109)) -> 13 | G10: =IF(E10=0,0,F10/E10) -> 1 | H10: =IF(G10<Cov_Pillar,"Not rated",IF(F10=0,"Not rated",AVERAGEIFS('Egypt (worked)'!$L$8:$L$109,'Egypt (worked)'!$D$8:$D$109,"C3"))) -> 3.1538462 | I10: =IF(NOT(ISNUMBER(H10)),H10,IF(H10<BandL2_from,"Nascent",IF(H10<BandL3_from,"Emerging",IF(H10<BandL4_from,"Established",IF(H10<BandL5_from,"Advanced","Transformative"))))) -> Established | J10: =IF(G10<Cov_Pillar,"⚑ COVERAGE",IF(SUMPRODUCT(('Egypt (worked)'!$D$8:$D$109="C3")*('Egypt (worked)'!$O$8:$O$109="STALE"))>0,"⚑ Stale evidence","")) -> ⚑ Stale evidence
B11: C4 | C11: Human & institutional capacity | D11: Capability | E11: =COUNTIF('Egypt (worked)'!$D$8:$D$109,"C4") -> 14 | F11: =SUMPRODUCT(('Egypt (worked)'!$D$8:$D$109="C4")*ISNUMBER('Egypt (worked)'!$L$8:$L$109)) -> 13 | G11: =IF(E11=0,0,F11/E11) -> 0.92857143 | H11: =IF(G11<Cov_Pillar,"Not rated",IF(F11=0,"Not rated",AVERAGEIFS('Egypt (worked)'!$L$8:$L$109,'Egypt (worked)'!$D$8:$D$109,"C4"))) -> 2.4615385 | I11: =IF(NOT(ISNUMBER(H11)),H11,IF(H11<BandL2_from,"Nascent",IF(H11<BandL3_from,"Emerging",IF(H11<BandL4_from,"Established",IF(H11<BandL5_from,"Advanced","Transformative"))))) -> Emerging | J11: =IF(G11<Cov_Pillar,"⚑ COVERAGE",IF(SUMPRODUCT(('Egypt (worked)'!$D$8:$D$109="C4")*('Egypt (worked)'!$O$8:$O$109="STALE"))>0,"⚑ Stale evidence","")) -> ⚑ Stale evidence
B12: E1 | C12: Innovation & private sector | D12: Ecosystem | E12: =COUNTIF('Egypt (worked)'!$D$8:$D$109,"E1") -> 14 | F12: =SUMPRODUCT(('Egypt (worked)'!$D$8:$D$109="E1")*ISNUMBER('Egypt (worked)'!$L$8:$L$109)) -> 13 | G12: =IF(E12=0,0,F12/E12) -> 0.92857143 | H12: =IF(G12<Cov_Pillar,"Not rated",IF(F12=0,"Not rated",AVERAGEIFS('Egypt (worked)'!$L$8:$L$109,'Egypt (worked)'!$D$8:$D$109,"E1"))) -> 3 | I12: =IF(NOT(ISNUMBER(H12)),H12,IF(H12<BandL2_from,"Nascent",IF(H12<BandL3_from,"Emerging",IF(H12<BandL4_from,"Established",IF(H12<BandL5_from,"Advanced","Transformative"))))) -> Established | J12: =IF(G12<Cov_Pillar,"⚑ COVERAGE",IF(SUMPRODUCT(('Egypt (worked)'!$D$8:$D$109="E1")*('Egypt (worked)'!$O$8:$O$109="STALE"))>0,"⚑ Stale evidence","")) -> ⚑ Stale evidence
B13: E2 | C13: Responsible AI & emerging tech | D13: Ecosystem | E13: =COUNTIF('Egypt (worked)'!$D$8:$D$109,"E2") -> 12 | F13: =SUMPRODUCT(('Egypt (worked)'!$D$8:$D$109="E2")*ISNUMBER('Egypt (worked)'!$L$8:$L$109)) -> 12 | G13: =IF(E13=0,0,F13/E13) -> 1 | H13: =IF(G13<Cov_Pillar,"Not rated",IF(F13=0,"Not rated",AVERAGEIFS('Egypt (worked)'!$L$8:$L$109,'Egypt (worked)'!$D$8:$D$109,"E2"))) -> 2.6666667 | I13: =IF(NOT(ISNUMBER(H13)),H13,IF(H13<BandL2_from,"Nascent",IF(H13<BandL3_from,"Emerging",IF(H13<BandL4_from,"Established",IF(H13<BandL5_from,"Advanced","Transformative"))))) -> Established | J13: =IF(G13<Cov_Pillar,"⚑ COVERAGE",IF(SUMPRODUCT(('Egypt (worked)'!$D$8:$D$109="E2")*('Egypt (worked)'!$O$8:$O$109="STALE"))>0,"⚑ Stale evidence","")) -> ⚑ Stale evidence
B14: O1 | C14: Inclusion, sustainability & outcomes | D14: Outcome | E14: =COUNTIF('Egypt (worked)'!$D$8:$D$109,"O1") -> 17 | F14: =SUMPRODUCT(('Egypt (worked)'!$D$8:$D$109="O1")*ISNUMBER('Egypt (worked)'!$L$8:$L$109)) -> 17 | G14: =IF(E14=0,0,F14/E14) -> 1 | H14: =IF(G14<Cov_Pillar,"Not rated",IF(F14=0,"Not rated",AVERAGEIFS('Egypt (worked)'!$L$8:$L$109,'Egypt (worked)'!$D$8:$D$109,"O1"))) -> 2.4117647 | I14: =IF(NOT(ISNUMBER(H14)),H14,IF(H14<BandL2_from,"Nascent",IF(H14<BandL3_from,"Emerging",IF(H14<BandL4_from,"Established",IF(H14<BandL5_from,"Advanced","Transformative"))))) -> Emerging | J14: =IF(G14<Cov_Pillar,"⚑ COVERAGE",IF(SUMPRODUCT(('Egypt (worked)'!$D$8:$D$109="O1")*('Egypt (worked)'!$O$8:$O$109="STALE"))>0,"⚑ Stale evidence","")) -> ⚑ Stale evidence
B16: Composite read-outs
B17: Read-out | C17: Formula | D17: Coverage | E17: Score | F17: Band | G17: Stage-eligible?
B18: CMS | C18: Capability (C1×w + C2×w + C3×w + C4×w) — suppress if any pillar unrated | D18: =IF(SUM(E8:E11)=0,0,SUM(F8:F11)/SUM(E8:E11)) -> 0.98039216 | E18: =IF(OR(NOT(ISNUMBER(H8)),NOT(ISNUMBER(H9)),NOT(ISNUMBER(H10)),NOT(ISNUMBER(H11))),"Not rated",IF(D18<Cov_CMS,"Not rated",SUMPRODUCT(H8:H11,Config!$D$35:$D$38))) -> 3.0660839 | F18: =IF(NOT(ISNUMBER(E18)),E18,IF(E18<BandL2_from,"Nascent",IF(E18<BandL3_from,"Emerging",IF(E18<BandL4_from,"Established",IF(E18<BandL5_from,"Advanced","Transformative"))))) -> Established | G18: =IF(NOT(ISNUMBER(E18)),"No","Yes") -> Yes
B19: EMS | C19: Ecosystem (E1×w + E2×w) — suppress if any pillar unrated | D19: =IF(SUM(E12:E13)=0,0,SUM(F12:F13)/SUM(E12:E13)) -> 0.96153846 | E19: =IF(OR(NOT(ISNUMBER(H12)),NOT(ISNUMBER(H13))),"Not rated",IF(D19<Cov_EMS,"Not rated",SUMPRODUCT(H12:H13,Config!$D$39:$D$40))) -> 2.9 | F19: =IF(NOT(ISNUMBER(E19)),E19,IF(E19<BandL2_from,"Nascent",IF(E19<BandL3_from,"Emerging",IF(E19<BandL4_from,"Established",IF(E19<BandL5_from,"Advanced","Transformative"))))) -> Established | G19: =IF(NOT(ISNUMBER(E19)),"No","Yes") -> Yes
B20: OES | C20: Outcome (O1 mean) | D20: =IF(E14=0,0,F14/E14) -> 1 | E20: =IF(NOT(ISNUMBER(H14)),"Not rated",H14) -> 2.4117647 | F20: =IF(NOT(ISNUMBER(E20)),E20,IF(E20<BandL2_from,"Nascent",IF(E20<BandL3_from,"Emerging",IF(E20<BandL4_from,"Established",IF(E20<BandL5_from,"Advanced","Transformative"))))) -> Emerging | G20: =IF(NOT(ISNUMBER(E20)),"No","Yes") -> Yes
B22: Core-gate audit (14 prerequisites)
B23: Metric | C23: Count | D23: Meaning
B24: Core gates at L1 | C24: =SUMPRODUCT(('Egypt (worked)'!$G$8:$G$109="YES")*('Egypt (worked)'!$L$8:$L$109=1)) -> 0 | D24: Caps overall stage at Stage 1 if > 0
B25: Core gates unmeasured | C25: =SUMPRODUCT(('Egypt (worked)'!$G$8:$G$109="YES")*(NOT(ISNUMBER('Egypt (worked)'!$L$8:$L$109)))) -> 0 | D25: Suppresses overall stage if > 0
B26: Core gates ≥ L3 | C26: =SUMPRODUCT(('Egypt (worked)'!$G$8:$G$109="YES")*('Egypt (worked)'!$L$8:$L$109>=3)) -> 12 | D26: How many gates are already Established or better
B27: Overall stage (non-compensatory cascade)
B28: OVERALL STAGE | C28: =IF(C25>0,"Suppressed (unmeasured core gate)",IF(C24>0,"Stage 1 — Foundation constrained (core gate at L1)",IF(NOT(ISNUMBER(E18)),"Not rated (CMS coverage/pillar)",IF(AND(ISNUMBER(E18),E18>=Stage5_CMS,ISNUMBER(E19),E19>=Stage5_EMS,ISNUMBER(E20),E20>=Stage5_OES),"Stage 5 — Transformative",IF(AND(ISNUMBER(E18),E18>=Stage4_CMS,ISNUMBER(E19),E19>=Stage4_EMS,ISNUMBER(E20),E20>=Stage4_OES),"Stage 4 — Integrated scale",IF(AND(ISNUMBER(E18),E18>=Stage3_CMS,ISNUMBER(E19),E19>=Stage3_EMS),"Stage 3 — Ecosystem scaling",IF(ISNUMBER(E18),IF(E18>=Stage2_CMS,"Stage 2 — Capability building","Stage 1 — Foundation constrained"),"Not rated"))))))) -> Stage 2 — Capability building
B29: Claim status | C29: =IF("'Egypt (worked)'"="'Egypt (worked)'","ENGAGEMENT PACKAGE — pre-mandate. No stage is claimable until human validation.","Assessed — validated by government / evidence panel.") -> ENGAGEMENT PACKAGE — pre-mandate. No stage is claimable until human validation.
B30: Evidence adequacy & staleness
B31: Metric | C31: Value | D31: Meaning
B32: Weighted evidence adequacy | C32: =IFERROR((SUMPRODUCT(ISNUMBER('Egypt (worked)'!$L$8:$L$109)*('Egypt (worked)'!$M$8:$M$109="High"))*Conf_High+SUMPRODUCT(ISNUMBER('Egypt (worked)'!$L$8:$L$109)*('Egypt (worked)'!$M$8:$M$109="Medium"))*Conf_Medium+SUMPRODUCT(ISNUMBER('Egypt (worked)'!$L$8:$L$109)*('Egypt (worked)'!$M$8:$M$109="Low"))*Conf_Low)/SUMPRODUCT(ISNUMBER('Egypt (worked)'!$L$8:$L$109)*1),0) -> 0.57173913 | D32: 0.5+ required for the read-outs to stand (Ev_Min)
B33: Stale readings | C33: =COUNTIF('Egypt (worked)'!$O$8:$O$109,"STALE") -> 16 | D33: Observation year older than the indicator's max age
B34: Data gaps | C34: =SUMPRODUCT((NOT(ISNUMBER('Egypt (worked)'!$L$8:$L$109)))*('Egypt (worked)'!$D$8:$D$109<>"C0")) -> 2 | D34: Scored indicators with no assessor level AND no machine level
B35: Coverage — overall (scored pillars only) | C35: =SUMPRODUCT(ISNUMBER('Egypt (worked)'!$L$8:$L$109)*('Egypt (worked)'!$D$8:$D$109<>"C0"))/SUMPRODUCT(1*('Egypt (worked)'!$D$8:$D$109<>"C0")) -> 0.9787234 | D35: Share of scored indicators (excludes C0 context) that carry a level
B36: Fragile-progress (leapfrog) check
B37: Foundation vs Ecosystem gap | C37: =IF(AND(ISNUMBER(H8),ISNUMBER(E19)),H8-E19,"—") -> 0.91818182 | D37: =IF(NOT(ISNUMBER(C37)),"",IF(ABS(C37)>=Leapfrog_Gap,"⚑ FRAGILE PROGRESS — check sequencing","OK")) -> OK

Sheet Egypt (worked)
B2: Egypt — DAMM v1.4 assessment
B3: Live scoring. Edit columns I–R. Columns J, L, O are formulas.
B5: Assessment mode | C5: Comprehensive (draft, engagement package) | E5: Assessor | F5: World Bank task team (draft) | H5: Mandate date | I5: PRE-MANDATE — engagement package | K5: Reference year | L5: 2025
B7: ID | C7: Indicator | D7: Pillar | E7: Method | F7: Dir. | G7: Core gate | H7: Max age | I7: Value | J7: Machine L (auto) | K7: Assessor L | L7: Effective L | M7: Confidence | N7: Year | O7: Stale? | P7: Source | Q7: URL | R7: Notes / dissent
B8: 1.1 | C8: Agriculture value added per worker (constant 2015 USD) | D8: C0 | E8: Context profile (not aggregated) | F8: N/A | H8: 3 | I8: 8390.6 | J8: =IF(I8="","",IF(Indicators!$H$6<>"Quantitative threshold","",IF(Indicators!$I$6="Higher",IF(N(I8)>=Indicators!$O$6,5,IF(N(I8)>=Indicators!$N$6,4,IF(N(I8)>=Indicators!$M$6,3,IF(N(I8)>=Indicators!$L$6,2,1)))),IF(N(I8)<=Indicators!$O$6,5,IF(N(I8)<=Indicators!$N$6,4,IF(N(I8)<=Indicators!$M$6,3,IF(N(I8)<=Indicators!$L$6,2,1))))))) | L8: =IF(Indicators!$D$6="C0","",IF(K8<>"",K8,IF(J8<>"",J8,""))) | M8: High | N8: 2023 | O8: =IF(N8="","",IF(N8<($L$5-H8),"STALE","")) | P8: World Bank WDI (NV.AGR.EMPL.KD) | Q8: https://api.worldbank.org/v2/country/EGY/indicator/NV.AGR.EMPL.KD?format=json | R8: Latest confirmed annual WDI observation for Egypt is 2023 ($8,390.60); later WDI 2024/2025 figures are nowcasted/modeled.
B9: 1.2 | C9: Cereal yield (kg per hectare) | D9: C0 | E9: Context profile (not aggregated) | F9: N/A | H9: 3 | I9: 7402.2 | J9: =IF(I9="","",IF(Indicators!$H$7<>"Quantitative threshold","",IF(Indicators!$I$7="Higher",IF(N(I9)>=Indicators!$O$7,5,IF(N(I9)>=Indicators!$N$7,4,IF(N(I9)>=Indicators!$M$7,3,IF(N(I9)>=Indicators!$L$7,2,1)))),IF(N(I9)<=Indicators!$O$7,5,IF(N(I9)<=Indicators!$N$7,4,IF(N(I9)<=Indicators!$M$7,3,IF(N(I9)<=Indicators!$L$7,2,1))))))) | L9: =IF(Indicators!$D$7="C0","",IF(K9<>"",K9,IF(J9<>"",J9,""))) | M9: High | N9: 2023 | O9: =IF(N9="","",IF(N9<($L$5-H9),"STALE","")) | P9: World Bank WDI (AG.YLD.CREL.KG) | Q9: https://api.worldbank.org/v2/country/EGY/indicator/AG.YLD.CREL.KG?format=json | R9: Egypt has among the highest cereal yields globally due to intensive irrigated agriculture.
B10: 1.3 | C10: Employment in agriculture (% of total employment) | D10: C0 | E10: Context profile (not aggregated) | F10: N/A | H10: 3 | I10: 17.52 | J10: =IF(I10="","",IF(Indicators!$H$8<>"Quantitative threshold","",IF(Indicators!$I$8="Higher",IF(N(I10)>=Indicators!$O$8,5,IF(N(I10)>=Indicators!$N$8,4,IF(N(I10)>=Indicators!$M$8,3,IF(N(I10)>=Indicators!$L$8,2,1)))),IF(N(I10)<=Indicators!$O$8,5,IF(N(I10)<=Indicators!$N$8,4,IF(N(I10)<=Indicators!$M$8,3,IF(N(I10)<=Indicators!$L$8,2,1))))))) | L10: =IF(Indicators!$D$8="C0","",IF(K10<>"",K10,IF(J10<>"",J10,""))) | M10: Medium | N10: 2023 | O10: =IF(N10="","",IF(N10<($L$5-H10),"STALE","")) | P10: World Bank WDI (SL.AGR.EMPL.ZS) | Q10: https://api.worldbank.org/v2/country/EGY/indicator/SL.AGR.EMPL.ZS?format=json | R10: WDI series continues to publish nowcasted 2024/2025 values (~17.5%); using confirmed recent-year band as best estimate.
B11: 1.4 | C11: Food production index (2014-2016 = 100) | D11: C0 | E11: Context profile (not aggregated) | F11: N/A | H11: 3 | I11: 109.07 | J11: =IF(I11="","",IF(Indicators!$H$9<>"Quantitative threshold","",IF(Indicators!$I$9="Higher",IF(N(I11)>=Indicators!$O$9,5,IF(N(I11)>=Indicators!$N$9,4,IF(N(I11)>=Indicators!$M$9,3,IF(N(I11)>=Indicators!$L$9,2,1)))),IF(N(I11)<=Indicators!$O$9,5,IF(N(I11)<=Indicators!$N$9,4,IF(N(I11)<=Indicators!$M$9,3,IF(N(I11)<=Indicators!$L$9,2,1))))))) | L11: =IF(Indicators!$D$9="C0","",IF(K11<>"",K11,IF(J11<>"",J11,""))) | M11: High | N11: 2022 | O11: =IF(N11="","",IF(N11<($L$5-H11),"STALE","")) | P11: World Bank WDI (AG.PRD.FOOD.XD) | Q11: https://api.worldbank.org/v2/country/EGY/indicator/AG.PRD.FOOD.XD?format=json | R11: Most recent published FAO-sourced food production index value via WDI.
B12: 1.5 | C12: Post-harvest loss rate (%) | D12: C0 | E12: Context profile (not aggregated) | F12: N/A | H12: 2 | I12: 10-15% of agricultural income; up to 30% for fruit/vegetables | J12: =IF(I12="","",IF(Indicators!$H$10<>"Quantitative threshold","",IF(Indicators!$I$10="Higher",IF(N(I12)>=Indicators!$O$10,5,IF(N(I12)>=Indicators!$N$10,4,IF(N(I12)>=Indicators!$M$10,3,IF(N(I12)>=Indicators!$L$10,2,1)))),IF(N(I12)<=Indicators!$O$10,5,IF(N(I12)<=Indicators!$N$10,4,IF(N(I12)<=Indicators!$M$10,3,IF(N(I12)<=Indicators!$L$10,2,1))))))) | L12: =IF(Indicators!$D$10="C0","",IF(K12<>"",K12,IF(J12<>"",J12,""))) | M12: Medium | N12: 2020 | O12: =IF(N12="","",IF(N12<($L$5-H12),"STALE","")) -> STALE | P12: FAO/MALR, Sustainable Agricultural Development Strategy towards 2030 | Q12: https://faolex.fao.org/docs/pdf/egy141040E.pdf | R12: SADS 2030 strategy document (MALR/FAO) states pre/post-harvest losses exceed 30% in vegetables and fruit, 20% in legumes/tubers, 10% in cereals, equating to 10-15% of total agricultural income; FAO Egypt food-loss project separately cites 15-45% depending on crop.
B13: 1.6 | C13: Smallholder access to formal markets (%) | D13: C0 | E13: Context profile (not aggregated) | F13: N/A | H13: 2 | I13: ~12% (Upper Egypt) | J13: =IF(I13="","",IF(Indicators!$H$11<>"Quantitative threshold","",IF(Indicators!$I$11="Higher",IF(N(I13)>=Indicators!$O$11,5,IF(N(I13)>=Indicators!$N$11,4,IF(N(I13)>=Indicators!$M$11,3,IF(N(I13)>=Indicators!$L$11,2,1)))),IF(N(I13)<=Indicators!$O$11,5,IF(N(I13)<=Indicators!$N$11,4,IF(N(I13)<=Indicators!$M$11,3,IF(N(I13)<=Indicators!$L$11,2,1))))))) | L13: =IF(Indicators!$D$11="C0","",IF(K13<>"",K13,IF(J13<>"",J13,""))) | M13: Medium | N13: 2025 | O13: =IF(N13="","",IF(N13<($L$5-H13),"STALE","")) | P13: IFAD Executive Board Seminar Document EB-2025-OR-16 | Q13: https://webapps.ifad.org/members/eb-seminars/2025-11-25-EB-Consultations/docs/EB-2025-OR-16.pdf | R13: IFAD reports only about 12% of farmers in Upper Egypt have direct links to formal buyers; no comprehensive national figure found, so this is a regional proxy.
B14: 1.7 | C14: Agricultural credit access (% of farmers) | D14: C0 | E14: Context profile (not aggregated) | F14: N/A | H14: 2 | I14: <25% financially included; ag sector receives ~1% of institutional lending | J14: =IF(I14="","",IF(Indicators!$H$12<>"Quantitative threshold","",IF(Indicators!$I$12="Higher",IF(N(I14)>=Indicators!$O$12,5,IF(N(I14)>=Indicators!$N$12,4,IF(N(I14)>=Indicators!$M$12,3,IF(N(I14)>=Indicators!$L$12,2,1)))),IF(N(I14)<=Indicators!$O$12,5,IF(N(I14)<=Indicators!$N$12,4,IF(N(I14)<=Indicators!$M$12,3,IF(N(I14)<=Indicators!$L$12,2,1))))))) | L14: =IF(Indicators!$D$12="C0","",IF(K14<>"",K14,IF(J14<>"",J14,""))) | M14: Medium | N14: 2021 | O14: =IF(N14="","",IF(N14<($L$5-H14),"STALE","")) -> STALE | P14: World Bank / MDPI 2024 citing WB 2021 Findex | Q14: https://www.mdpi.com/1911-8074/17/11/487 | R14: Less than 25% of Egypt's rural population is financially included per bank account ownership (World Bank 2021, cited in 2024 MDPI study); older World Bank data show agriculture receiving only ~1% of total institutional lending versus 38%/26% for industry/services.
B15: 1.8 | C15: Farmers using climate-smart/sustainable practices (%) | D15: C0 | E15: Context profile (not aggregated) | F15: N/A | H15: 2 | J15: =IF(I15="","",IF(Indicators!$H$13<>"Quantitative threshold","",IF(Indicators!$I$13="Higher",IF(N(I15)>=Indicators!$O$13,5,IF(N(I15)>=Indicators!$N$13,4,IF(N(I15)>=Indicators!$M$13,3,IF(N(I15)>=Indicators!$L$13,2,1)))),IF(N(I15)<=Indicators!$O$13,5,IF(N(I15)<=Indicators!$N$13,4,IF(N(I15)<=Indicators!$M$13,3,IF(N(I15)<=Indicators!$L$13,2,1))))))) | K15: 2 | L15: =IF(Indicators!$D$13="C0","",IF(K15<>"",K15,IF(J15<>"",J15,""))) | M15: Low | N15: 2020 | O15: =IF(N15="","",IF(N15<($L$5-H15),"STALE","")) -> STALE | P15: SADS 2030 (qualitative; no adoption-rate survey found) | Q15: https://faolex.fao.org/docs/pdf/egy141040E.pdf | R15: SADS 2030 sets climate-smart and water-efficiency ambitions but does not publish a measured adoption rate among farmers; assessed level 2 (aspirational policy target, adoption not yet measured/scaled) rather than a Data Gap given the strategy explicitly frames this as a named priority.
B16: 1.9 | C16: National innovation/extension programs with digital component | D16: C4 | E16: Anchored capability rubric | F16: N/A | H16: 2 | J16: =IF(I16="","",IF(Indicators!$H$14<>"Quantitative threshold","",IF(Indicators!$I$14="Higher",IF(N(I16)>=Indicators!$O$14,5,IF(N(I16)>=Indicators!$N$14,4,IF(N(I16)>=Indicators!$M$14,3,IF(N(I16)>=Indicators!$L$14,2,1)))),IF(N(I16)<=Indicators!$O$14,5,IF(N(I16)<=Indicators!$N$14,4,IF(N(I16)<=Indicators!$M$14,3,IF(N(I16)<=Indicators!$L$14,2,1))))))) | K16: 4 | L16: =IF(Indicators!$D$14="C0","",IF(K16<>"",K16,IF(J16<>"",J16,""))) -> 4 | M16: Medium | N16: 2025 | O16: =IF(N16="","",IF(N16<($L$5-H16),"STALE","")) | P16: MALR/MCIT program review; FAO; GIZ | Q16: https://www.sis.gov.eg/Story/193871/Digital-transformation-in-agro-sector-reviewed?lang=en-us | R16: Multiple active digital-extension programs exist (Hudhud AI pest ID, El Mufeed advisory app, Morshed Zaki AI chatbot pilot with GIZ, crop-mapping/satellite project) reviewed at ministerial level in Sept 2025, indicating an established but still-maturing digital extension ecosystem — assessed at level 4 (established, multiple programs, government-led coordination) rather than 5 (fully integrated/scaled).
B17: 2.1 | C17: Rural population covered by at least 3G (%) | D17: C1 | E17: Quantitative threshold | F17: Higher | G17: YES | H17: 3 | I17: 99.8 | J17: =IF(I17="","",IF(Indicators!$H$15<>"Quantitative threshold","",IF(Indicators!$I$15="Higher",IF(N(I17)>=Indicators!$O$15,5,IF(N(I17)>=Indicators!$N$15,4,IF(N(I17)>=Indicators!$M$15,3,IF(N(I17)>=Indicators!$L$15,2,1)))),IF(N(I17)<=Indicators!$O$15,5,IF(N(I17)<=Indicators!$N$15,4,IF(N(I17)<=Indicators!$M$15,3,IF(N(I17)<=Indicators!$L$15,2,1))))))) -> 5 | L17: =IF(Indicators!$D$15="C0","",IF(K17<>"",K17,IF(J17<>"",J17,""))) -> 5 | M17: High | N17: 2024 | O17: =IF(N17="","",IF(N17<($L$5-H17),"STALE","")) | P17: ITU DataHub / ITU IDI Dataset | Q17: https://datahub.itu.int/docs/IDIDataset.xlsx | R17: CORE GATE. ITU DataHub IDI dataset population-covered-by-3G figure for Egypt is near-universal (~99.8%), consistent with ITU DDD Egypt profile showing 100% network population coverage for 3G in 2022.
B18: 2.2 | C18: Rural population covered by at least 4G (%) | D18: C1 | E18: Quantitative threshold | F18: Higher | H18: 3 | I18: 98 | J18: =IF(I18="","",IF(Indicators!$H$16<>"Quantitative threshold","",IF(Indicators!$I$16="Higher",IF(N(I18)>=Indicators!$O$16,5,IF(N(I18)>=Indicators!$N$16,4,IF(N(I18)>=Indicators!$M$16,3,IF(N(I18)>=Indicators!$L$16,2,1)))),IF(N(I18)<=Indicators!$O$16,5,IF(N(I18)<=Indicators!$N$16,4,IF(N(I18)<=Indicators!$M$16,3,IF(N(I18)<=Indicators!$L$16,2,1))))))) -> 5 | L18: =IF(Indicators!$D$16="C0","",IF(K18<>"",K18,IF(J18<>"",J18,""))) -> 5 | M18: High | N18: 2024 | O18: =IF(N18="","",IF(N18<($L$5-H18),"STALE","")) | P18: ITU DataHub / ITU IDI Dataset | Q18: https://datahub.itu.int/docs/IDIDataset.xlsx | R18: ITU IDI dataset shows ~98% population 4G coverage; ITU DDD Egypt profile (2022) reports 98% 4G network coverage nationally.
B19: 2.3 | C19: Active mobile broadband subscriptions per 100 inhabitants | D19: C1 | E19: Quantitative threshold | F19: Higher | H19: 3 | I19: 75 | J19: =IF(I19="","",IF(Indicators!$H$17<>"Quantitative threshold","",IF(Indicators!$I$17="Higher",IF(N(I19)>=Indicators!$O$17,5,IF(N(I19)>=Indicators!$N$17,4,IF(N(I19)>=Indicators!$M$17,3,IF(N(I19)>=Indicators!$L$17,2,1)))),IF(N(I19)<=Indicators!$O$17,5,IF(N(I19)<=Indicators!$N$17,4,IF(N(I19)<=Indicators!$M$17,3,IF(N(I19)<=Indicators!$L$17,2,1))))))) -> 4 | L19: =IF(Indicators!$D$17="C0","",IF(K19<>"",K19,IF(J19<>"",J19,""))) -> 4 | M19: High | N19: 2024 | O19: =IF(N19="","",IF(N19<($L$5-H19),"STALE","")) | P19: ITU DataHub / ITU IDI Dataset | Q19: https://datahub.itu.int/docs/IDIDataset.xlsx | R19: ITU IDI dataset active mobile-broadband subscriptions per 100 inhabitants for Egypt.
B20: 2.4 | C20: Individuals using the Internet (% of population) | D20: C1 | E20: Quantitative threshold | F20: Higher | H20: 3 | I20: 74.65 | J20: =IF(I20="","",IF(Indicators!$H$18<>"Quantitative threshold","",IF(Indicators!$I$18="Higher",IF(N(I20)>=Indicators!$O$18,5,IF(N(I20)>=Indicators!$N$18,4,IF(N(I20)>=Indicators!$M$18,3,IF(N(I20)>=Indicators!$L$18,2,1)))),IF(N(I20)<=Indicators!$O$18,5,IF(N(I20)<=Indicators!$N$18,4,IF(N(I20)<=Indicators!$M$18,3,IF(N(I20)<=Indicators!$L$18,2,1))))))) -> 4 | L20: =IF(Indicators!$D$18="C0","",IF(K20<>"",K20,IF(J20<>"",J20,""))) -> 4 | M20: High | N20: 2024 | O20: =IF(N20="","",IF(N20<($L$5-H20),"STALE","")) | P20: World Bank WDI (IT.NET.USER.ZS), ITU source | Q20: https://api.worldbank.org/v2/country/EGY/indicator/IT.NET.USER.ZS?format=json | R20: WDI figure (ITU-sourced) for internet users. Note DataReportal's Digital 2025 Egypt report gives a higher figure (81.9%, Jan 2025) using a different survey methodology — both cited for context.
B21: 2.5 | C21: Mobile broadband basket price (% GNI per capita) | D21: C1 | E21: Quantitative threshold | F21: Lower | G21: YES | H21: 3 | I21: 1.2 | J21: =IF(I21="","",IF(Indicators!$H$19<>"Quantitative threshold","",IF(Indicators!$I$19="Higher",IF(N(I21)>=Indicators!$O$19,5,IF(N(I21)>=Indicators!$N$19,4,IF(N(I21)>=Indicators!$M$19,3,IF(N(I21)>=Indicators!$L$19,2,1)))),IF(N(I21)<=Indicators!$O$19,5,IF(N(I21)<=Indicators!$N$19,4,IF(N(I21)<=Indicators!$M$19,3,IF(N(I21)<=Indicators!$L$19,2,1))))))) -> 4 | L21: =IF(Indicators!$D$19="C0","",IF(K21<>"",K21,IF(J21<>"",J21,""))) -> 4 | M21: High | N21: 2024 | O21: =IF(N21="","",IF(N21<($L$5-H21),"STALE","")) | P21: ITU DataHub / ENCC Egypt | Q21: https://encc-eg.org/en/pressroom/press.aspx?id=514 | R21: CORE GATE. ITU IDI mobile data+voice basket price for Egypt is in the 1.1-1.4% of GNI per capita range, well under the UN Broadband Commission 2% affordability target.
B22: 2.6 | C22: Adults with mobile phone (% age 15+) | D22: C1 | E22: Quantitative threshold | F22: Higher | H22: 3 | I22: 97.13 | J22: =IF(I22="","",IF(Indicators!$H$20<>"Quantitative threshold","",IF(Indicators!$I$20="Higher",IF(N(I22)>=Indicators!$O$20,5,IF(N(I22)>=Indicators!$N$20,4,IF(N(I22)>=Indicators!$M$20,3,IF(N(I22)>=Indicators!$L$20,2,1)))),IF(N(I22)<=Indicators!$O$20,5,IF(N(I22)<=Indicators!$N$20,4,IF(N(I22)<=Indicators!$M$20,3,IF(N(I22)<=Indicators!$L$20,2,1))))))) -> 5 | L22: =IF(Indicators!$D$20="C0","",IF(K22<>"",K22,IF(J22<>"",J22,""))) -> 5 | M22: Medium | N22: 2024 | O22: =IF(N22="","",IF(N22<($L$5-H22),"STALE","")) | P22: World Bank WDI (IT.CEL.SETS.P2, mobile cellular subscriptions per 100) | Q22: https://api.worldbank.org/v2/country/EGY/indicator/IT.CEL.SETS.P2?format=json | R22: Using mobile-cellular-subscriptions-per-100 (97.1) as a proxy for adult mobile phone ownership since a direct 15+ ownership rate was not located; MCIT Q2 2024 bulletin corroborates penetration of ~101.9% (subscriptions, not unique users).
B23: 2.7 | C23: Smartphone ownership among rural/agricultural population (%) | D23: C1 | E23: Quantitative threshold | F23: Higher | H23: 2 | I23: 13.9 | J23: =IF(I23="","",IF(Indicators!$H$21<>"Quantitative threshold","",IF(Indicators!$I$21="Higher",IF(N(I23)>=Indicators!$O$21,5,IF(N(I23)>=Indicators!$N$21,4,IF(N(I23)>=Indicators!$M$21,3,IF(N(I23)>=Indicators!$L$21,2,1)))),IF(N(I23)<=Indicators!$O$21,5,IF(N(I23)<=Indicators!$N$21,4,IF(N(I23)<=Indicators!$M$21,3,IF(N(I23)<=Indicators!$L$21,2,1))))))) -> 1 | L23: =IF(Indicators!$D$21="C0","",IF(K23<>"",K23,IF(J23<>"",J23,""))) -> 1 | M23: Low | N23: 2015 | O23: =IF(N23="","",IF(N23<($L$5-H23),"STALE","")) -> STALE | P23: CAPMAS 2015 household survey (via Ahram Online) | Q23: https://english.ahram.org.eg/NewsContent/3/12/236203/-.aspx | R23: Only figure located is dated (CAPMAS 2015): 13.9% smartphone ownership in rural households vs 31.7% urban; exceeds MaxAge, likely understates 2025-26 penetration given intervening smartphone price declines — flagged Low/Estimated confidence pending an updated survey.
B24: 2.8 | C24: Average mobile data cost in rural areas (USD per GB) | D24: C1 | E24: Quantitative threshold | F24: Lower | H24: 2 | J24: =IF(I24="","",IF(Indicators!$H$22<>"Quantitative threshold","",IF(Indicators!$I$22="Higher",IF(N(I24)>=Indicators!$O$22,5,IF(N(I24)>=Indicators!$N$22,4,IF(N(I24)>=Indicators!$M$22,3,IF(N(I24)>=Indicators!$L$22,2,1)))),IF(N(I24)<=Indicators!$O$22,5,IF(N(I24)<=Indicators!$N$22,4,IF(N(I24)<=Indicators!$M$22,3,IF(N(I24)<=Indicators!$L$22,2,1))))))) | K24: 3 | L24: =IF(Indicators!$D$22="C0","",IF(K24<>"",K24,IF(J24<>"",J24,""))) -> 3 | M24: Low | N24: 2024 | O24: =IF(N24="","",IF(N24<($L$5-H24),"STALE","")) | P24: Proxy: ITU mobile data+voice basket (~1.1-1.4% GNI p.c. national average) | Q24: https://encc-eg.org/en/pressroom/press.aspx?id=514 | R24: No rural-specific mobile data cost breakdown was found; the national mobile data+voice basket price (1.1-1.4% of GNI per capita) is used as an affordability proxy, well within global affordability benchmarks, so assessed level 3 pending a rural-specific figure.
B25: 2.9 | C25: Electricity access in rural areas (%) | D25: C1 | E25: Quantitative threshold | F25: Higher | G25: YES | H25: 2 | I25: 100 | J25: =IF(I25="","",IF(Indicators!$H$23<>"Quantitative threshold","",IF(Indicators!$I$23="Higher",IF(N(I25)>=Indicators!$O$23,5,IF(N(I25)>=Indicators!$N$23,4,IF(N(I25)>=Indicators!$M$23,3,IF(N(I25)>=Indicators!$L$23,2,1)))),IF(N(I25)<=Indicators!$O$23,5,IF(N(I25)<=Indicators!$N$23,4,IF(N(I25)<=Indicators!$M$23,3,IF(N(I25)<=Indicators!$L$23,2,1))))))) -> 5 | L25: =IF(Indicators!$D$23="C0","",IF(K25<>"",K25,IF(J25<>"",J25,""))) -> 5 | M25: High | N25: 2024 | O25: =IF(N25="","",IF(N25<($L$5-H25),"STALE","")) | P25: World Bank WDI (EG.ELC.ACCS.RU.ZS) | Q25: https://api.worldbank.org/v2/country/EGY/indicator/EG.ELC.ACCS.RU.ZS?format=json | R25: CORE GATE. Egypt has achieved universal (100%) rural electricity access per WDI.
B26: 2.10 | C26: Average download speed in agricultural areas (Mbps) | D26: C1 | E26: Quantitative threshold | F26: Higher | H26: 2 | I26: 24.17 | J26: =IF(I26="","",IF(Indicators!$H$24<>"Quantitative threshold","",IF(Indicators!$I$24="Higher",IF(N(I26)>=Indicators!$O$24,5,IF(N(I26)>=Indicators!$N$24,4,IF(N(I26)>=Indicators!$M$24,3,IF(N(I26)>=Indicators!$L$24,2,1)))),IF(N(I26)<=Indicators!$O$24,5,IF(N(I26)<=Indicators!$N$24,4,IF(N(I26)<=Indicators!$M$24,3,IF(N(I26)<=Indicators!$L$24,2,1))))))) -> 4 | L26: =IF(Indicators!$D$24="C0","",IF(K26<>"",K26,IF(J26<>"",J26,""))) -> 4 | M26: Low | N26: 2025 | O26: =IF(N26="","",IF(N26<($L$5-H26),"STALE","")) | P26: Ookla via DataReportal Digital 2025 Egypt (national median, proxy) | Q26: https://datareportal.com/reports/digital-2025-egypt | R26: No agriculture-area-specific broadband speed data was found; using the national median mobile download speed (24.17 Mbps, up from 22.11 Mbps in 2024) as a proxy since rural/agricultural-zone-specific measurement is unavailable.
B27: 2.11 | C27: Device financing/subsidy schemes for farmers | D27: C1 | E27: Anchored capability rubric | F27: N/A | H27: 2 | J27: =IF(I27="","",IF(Indicators!$H$25<>"Quantitative threshold","",IF(Indicators!$I$25="Higher",IF(N(I27)>=Indicators!$O$25,5,IF(N(I27)>=Indicators!$N$25,4,IF(N(I27)>=Indicators!$M$25,3,IF(N(I27)>=Indicators!$L$25,2,1)))),IF(N(I27)<=Indicators!$O$25,5,IF(N(I27)<=Indicators!$N$25,4,IF(N(I27)<=Indicators!$M$25,3,IF(N(I27)<=Indicators!$L$25,2,1))))))) | K27: 2 | L27: =IF(Indicators!$D$25="C0","",IF(K27<>"",K27,IF(J27<>"",J27,""))) -> 2 | M27: Low | N27: 2025 | O27: =IF(N27="","",IF(N27<($L$5-H27),"STALE","")) | P27: Sector review (no dedicated scheme identified) | R27: No dedicated national device-financing/subsidy scheme specifically for farmers was identified; general consumer device financing exists in the broader Egyptian market but not targeted at farmers — assessed at a low maturity level (2) as an emerging/ad hoc capability.
B28: 3.1 | C28: UN E-Government Development Index (EGDI) | D28: C2 | E28: Quantitative threshold | F28: Higher | H28: 3 | I28: 0.6699 | J28: =IF(I28="","",IF(Indicators!$H$26<>"Quantitative threshold","",IF(Indicators!$I$26="Higher",IF(N(I28)>=Indicators!$O$26,5,IF(N(I28)>=Indicators!$N$26,4,IF(N(I28)>=Indicators!$M$26,3,IF(N(I28)>=Indicators!$L$26,2,1)))),IF(N(I28)<=Indicators!$O$26,5,IF(N(I28)<=Indicators!$N$26,4,IF(N(I28)<=Indicators!$M$26,3,IF(N(I28)<=Indicators!$L$26,2,1))))))) -> 4 | L28: =IF(Indicators!$D$26="C0","",IF(K28<>"",K28,IF(J28<>"",J28,""))) -> 4 | M28: High | N28: 2024 | O28: =IF(N28="","",IF(N28<($L$5-H28),"STALE","")) | P28: UN E-Government Survey 2024 | Q28: https://desapublications.un.org/sites/default/files/publications/2024-10/Chapter%203%20%20E-Government%20Survey%202024.pdf | R28: Egypt EGDI rose to 0.6699 (rank 95/193, rating H3) in the 2024 UN E-Government Survey, up from 0.5895 (rank 103) in 2022.
B29: 3.2 | C29: Open Data Inventory (ODIN) score | D29: C2 | E29: Quantitative threshold | F29: Higher | H29: 3 | J29: =IF(I29="","",IF(Indicators!$H$27<>"Quantitative threshold","",IF(Indicators!$I$27="Higher",IF(N(I29)>=Indicators!$O$27,5,IF(N(I29)>=Indicators!$N$27,4,IF(N(I29)>=Indicators!$M$27,3,IF(N(I29)>=Indicators!$L$27,2,1)))),IF(N(I29)<=Indicators!$O$27,5,IF(N(I29)<=Indicators!$N$27,4,IF(N(I29)<=Indicators!$M$27,3,IF(N(I29)<=Indicators!$L$27,2,1))))))) | K29: 2 | L29: =IF(Indicators!$D$27="C0","",IF(K29<>"",K29,IF(J29<>"",J29,""))) -> 2 | M29: Low | N29: 2022 | O29: =IF(N29="","",IF(N29<($L$5-H29),"STALE","")) | P29: Open Data Watch ODIN (score not numerically confirmed; qualitative placement only) | Q29: https://odin.opendatawatch.com/ | R29: Direct retrieval of Egypt's numeric ODIN score/rank from Open Data Watch's country-profile and rankings pages did not return extractable data in this session. Egypt does not have a strong open-data reputation in adjacent benchmarks (no dedicated national ag open-data portal per indicator 3.5; general EGDI Online Service Index of 0.70 suggests moderate but incomplete e-government data openness) — assessed a cautious level 2 pending direct confirmation of the official ODIN score.
B30: 3.3 | C30: National farmer registry/database | D30: C2 | E30: Anchored capability rubric | F30: N/A | G30: YES | H30: 2 | J30: =IF(I30="","",IF(Indicators!$H$28<>"Quantitative threshold","",IF(Indicators!$I$28="Higher",IF(N(I30)>=Indicators!$O$28,5,IF(N(I30)>=Indicators!$N$28,4,IF(N(I30)>=Indicators!$M$28,3,IF(N(I30)>=Indicators!$L$28,2,1)))),IF(N(I30)<=Indicators!$O$28,5,IF(N(I30)<=Indicators!$N$28,4,IF(N(I30)<=Indicators!$M$28,3,IF(N(I30)<=Indicators!$L$28,2,1))))))) | K30: 4 | L30: =IF(Indicators!$D$28="C0","",IF(K30<>"",K30,IF(J30<>"",J30,""))) -> 4 | M30: Medium | N30: 2025 | O30: =IF(N30="","",IF(N30<($L$5-H30),"STALE","")) | P30: MALR Farmer Card / Meeza Farmer Card system | Q30: https://oxfordbusinessgroup.com/reports/egypt/2022-report/economy/tools-of-the-trade-digitalisation-is-key-to-efforts-to-bolster-food-and-water-security | R30: CORE GATE. Egypt operates a national 'Farmer Card' smart-card registry (since 2016) recording landholding, quota, and subsidy data, digitally linked since 2020 to the Meeza payment system and Agricultural Bank of Egypt for subsidized lending — an operating, integrated registry, assessed level 4 (established and linked to financial services) short of level 5 (fully interoperable across all ag programs).
B31: 3.4 | C31: Digital land/plot registration system | D31: C2 | E31: Anchored capability rubric | F31: N/A | H31: 2 | J31: =IF(I31="","",IF(Indicators!$H$29<>"Quantitative threshold","",IF(Indicators!$I$29="Higher",IF(N(I31)>=Indicators!$O$29,5,IF(N(I31)>=Indicators!$N$29,4,IF(N(I31)>=Indicators!$M$29,3,IF(N(I31)>=Indicators!$L$29,2,1)))),IF(N(I31)<=Indicators!$O$29,5,IF(N(I31)<=Indicators!$N$29,4,IF(N(I31)<=Indicators!$M$29,3,IF(N(I31)<=Indicators!$L$29,2,1))))))) | K31: 3 | L31: =IF(Indicators!$D$29="C0","",IF(K31<>"",K31,IF(J31<>"",J31,""))) -> 3 | M31: Medium | N31: 2026 | O31: =IF(N31="","",IF(N31<($L$5-H31),"STALE","")) | P31: Ministry of Justice / ESA cadastre modernization; Ahram Online | Q31: https://english.ahram.org.eg/News/560931.aspx | R31: Egypt has a long-running but incomplete land registration digitization effort (Nationwide Title Cadastre System since ~2005); a new digital platform for informal land legalization (Law 168/2025) launched May 2026 (nplr.estrdad.gov.eg), indicating continued modernization but not yet comprehensive national coverage — assessed level 3 (partial/piloting).
B32: 3.5 | C32: National agricultural data portal / open data | D32: C2 | E32: Anchored capability rubric | F32: N/A | H32: 2 | J32: =IF(I32="","",IF(Indicators!$H$30<>"Quantitative threshold","",IF(Indicators!$I$30="Higher",IF(N(I32)>=Indicators!$O$30,5,IF(N(I32)>=Indicators!$N$30,4,IF(N(I32)>=Indicators!$M$30,3,IF(N(I32)>=Indicators!$L$30,2,1)))),IF(N(I32)<=Indicators!$O$30,5,IF(N(I32)<=Indicators!$N$30,4,IF(N(I32)<=Indicators!$M$30,3,IF(N(I32)<=Indicators!$L$30,2,1))))))) | K32: 2 | L32: =IF(Indicators!$D$30="C0","",IF(K32<>"",K32,IF(J32<>"",J32,""))) -> 2 | M32: Low | N32: 2025 | O32: =IF(N32="","",IF(N32<($L$5-H32),"STALE","")) | P32: Sector review | R32: No single comprehensive national agricultural open-data portal was identified; MALR/MCIT projects (Digital Egypt integration, crop-mapping) suggest data exists internally but is not clearly published as an open portal — assessed level 2 (early-stage/fragmented).
B33: 3.6 | C33: Weather/climate data infrastructure for agriculture | D33: C2 | E33: Anchored capability rubric | F33: N/A | H33: 2 | J33: =IF(I33="","",IF(Indicators!$H$31<>"Quantitative threshold","",IF(Indicators!$I$31="Higher",IF(N(I33)>=Indicators!$O$31,5,IF(N(I33)>=Indicators!$N$31,4,IF(N(I33)>=Indicators!$M$31,3,IF(N(I33)>=Indicators!$L$31,2,1)))),IF(N(I33)<=Indicators!$O$31,5,IF(N(I33)<=Indicators!$N$31,4,IF(N(I33)<=Indicators!$M$31,3,IF(N(I33)<=Indicators!$L$31,2,1))))))) | K33: 3 | L33: =IF(Indicators!$D$31="C0","",IF(K33<>"",K33,IF(J33<>"",J33,""))) -> 3 | M33: Medium | N33: 2025 | O33: =IF(N33="","",IF(N33<($L$5-H33),"STALE","")) | P33: DAIRS climate early-warning system (per CGIAR/ICARDA review) | Q33: https://cgspace.cgiar.org/server/api/core/bitstreams/d4a33acc-564a-4e4c-a413-81ba3ebd4d90/content | R33: Government-led DAIRS climate early-warning system is under development/limited rollout per ICARDA 2025 review; functioning but not yet at full national scale — assessed level 3.
B34: 3.7 | C34: Satellite/earth observation data integration capability | D34: C2 | E34: Anchored capability rubric | F34: N/A | H34: 2 | J34: =IF(I34="","",IF(Indicators!$H$32<>"Quantitative threshold","",IF(Indicators!$I$32="Higher",IF(N(I34)>=Indicators!$O$32,5,IF(N(I34)>=Indicators!$N$32,4,IF(N(I34)>=Indicators!$M$32,3,IF(N(I34)>=Indicators!$L$32,2,1)))),IF(N(I34)<=Indicators!$O$32,5,IF(N(I34)<=Indicators!$N$32,4,IF(N(I34)<=Indicators!$M$32,3,IF(N(I34)<=Indicators!$L$32,2,1))))))) | K34: 4 | L34: =IF(Indicators!$D$32="C0","",IF(K34<>"",K34,IF(J34<>"",J34,""))) -> 4 | M34: Medium | N34: 2025 | O34: =IF(N34="","",IF(N34<($L$5-H34),"STALE","")) | P34: SIS.gov.eg MALR/MCIT crop-mapping project review | Q34: https://www.sis.gov.eg/Story/193871/Digital-transformation-in-agro-sector-reviewed?lang=en-us | R34: Egypt has an active MALR-MCIT project using AI and satellite imagery to map agricultural land, forecast crop yields, and monitor pests (reviewed September 2025) — an operating capability, assessed level 4.
B35: 3.8 | C35: National soil map/database (digital) | D35: C2 | E35: Anchored capability rubric | F35: N/A | H35: 2 | J35: =IF(I35="","",IF(Indicators!$H$33<>"Quantitative threshold","",IF(Indicators!$I$33="Higher",IF(N(I35)>=Indicators!$O$33,5,IF(N(I35)>=Indicators!$N$33,4,IF(N(I35)>=Indicators!$M$33,3,IF(N(I35)>=Indicators!$L$33,2,1)))),IF(N(I35)<=Indicators!$O$33,5,IF(N(I35)<=Indicators!$N$33,4,IF(N(I35)<=Indicators!$M$33,3,IF(N(I35)<=Indicators!$L$33,2,1))))))) | K35: 2 | L35: =IF(Indicators!$D$33="C0","",IF(K35<>"",K35,IF(J35<>"",J35,""))) -> 2 | M35: Low | N35: 2025 | O35: =IF(N35="","",IF(N35<($L$5-H35),"STALE","")) | P35: Sector review | R35: No verified evidence of a comprehensive, publicly accessible digital national soil map/database for Egypt was located in this search; historical soil surveys exist but digitization status is unclear — assessed level 2 pending further evidence.
B36: 3.9 | C36: Digital advisory platforms reaching >10,000 users | D36: C2 | E36: Quantitative threshold | F36: Higher | H36: 2 | I36: 100,000+ users (Mahsoly, AlMorshed Poultry); 10,000+ (several other advisory platforms) | J36: =IF(I36="","",IF(Indicators!$H$34<>"Quantitative threshold","",IF(Indicators!$I$34="Higher",IF(N(I36)>=Indicators!$O$34,5,IF(N(I36)>=Indicators!$N$34,4,IF(N(I36)>=Indicators!$M$34,3,IF(N(I36)>=Indicators!$L$34,2,1)))),IF(N(I36)<=Indicators!$O$34,5,IF(N(I36)<=Indicators!$N$34,4,IF(N(I36)<=Indicators!$M$34,3,IF(N(I36)<=Indicators!$L$34,2,1))))))) -> 1 | K36: 4 | L36: =IF(Indicators!$D$34="C0","",IF(K36<>"",K36,IF(J36<>"",J36,""))) -> 4 | M36: Medium | N36: 2025 | O36: =IF(N36="","",IF(N36<($L$5-H36),"STALE","")) | P36: CGIAR/ICARDA digital agriculture review | Q36: https://cgspace.cgiar.org/server/api/core/bitstreams/9f8108a1-d7e7-54a1-8527-3111f8e4bfc0/content | R36: ICARDA 2025 review reports Mahsoly and AlMorshed Poultry each reaching 100,000+ users, with several other advisory platforms (El-Mufeed, Mazra3ty, Fila7a) reaching 10,000+ — clear threshold pass, assessed level 4.
B37: 3.10 | C37: Digital agricultural market/e-commerce platforms (>5,000 active users) | D37: C2 | E37: Anchored capability rubric | F37: N/A | H37: 2 | J37: =IF(I37="","",IF(Indicators!$H$35<>"Quantitative threshold","",IF(Indicators!$I$35="Higher",IF(N(I37)>=Indicators!$O$35,5,IF(N(I37)>=Indicators!$N$35,4,IF(N(I37)>=Indicators!$M$35,3,IF(N(I37)>=Indicators!$L$35,2,1)))),IF(N(I37)<=Indicators!$O$35,5,IF(N(I37)<=Indicators!$N$35,4,IF(N(I37)<=Indicators!$M$35,3,IF(N(I37)<=Indicators!$L$35,2,1))))))) | K37: 3 | L37: =IF(Indicators!$D$35="C0","",IF(K37<>"",K37,IF(J37<>"",J37,""))) -> 3 | M37: Medium | N37: 2025 | O37: =IF(N37="","",IF(N37<($L$5-H37),"STALE","")) | P37: Sector review (Mozare3, AgriCash, Mahsoly) | Q37: https://medium.com/@abdelrhmansoliman96/egypts-foodtech-market-map-2024-a-comprehensive-analysis-of-the-digital-food-ecosystem-cbcd6d81814f | R37: Mozare3 reports financing ~6,300 smallholder farmers (below the 5,000-active-user threshold but close), and platforms like Mahsoly report 100,000+ users for price-monitoring rather than transactional e-commerce; assessed level 3 (emerging, multiple platforms, uneven scale).
B38: 3.11 | C38: Interoperability standards for agricultural data | D38: C2 | E38: Anchored capability rubric | F38: N/A | G38: YES | H38: 2 | J38: =IF(I38="","",IF(Indicators!$H$36<>"Quantitative threshold","",IF(Indicators!$I$36="Higher",IF(N(I38)>=Indicators!$O$36,5,IF(N(I38)>=Indicators!$N$36,4,IF(N(I38)>=Indicators!$M$36,3,IF(N(I38)>=Indicators!$L$36,2,1)))),IF(N(I38)<=Indicators!$O$36,5,IF(N(I38)<=Indicators!$N$36,4,IF(N(I38)<=Indicators!$M$36,3,IF(N(I38)<=Indicators!$L$36,2,1))))))) | K38: 2 | L38: =IF(Indicators!$D$36="C0","",IF(K38<>"",K38,IF(J38<>"",J38,""))) -> 2 | M38: Low | N38: 2025 | O38: =IF(N38="","",IF(N38<($L$5-H38),"STALE","")) | P38: Sector review | R38: No dedicated agricultural-data interoperability standard was identified; broader Digital Egypt platform integration efforts exist across MALR/MCIT/ABE systems (Farmer Card, Meeza, Digital Egypt) but no documented common data standard for agriculture specifically — CORE GATE, assessed level 2 (ad hoc, bilateral integrations only).
B39: 3.12 | C39: AI-ready agricultural datasets | D39: C2 | E39: Anchored capability rubric | F39: N/A | H39: 2 | J39: =IF(I39="","",IF(Indicators!$H$37<>"Quantitative threshold","",IF(Indicators!$I$37="Higher",IF(N(I39)>=Indicators!$O$37,5,IF(N(I39)>=Indicators!$N$37,4,IF(N(I39)>=Indicators!$M$37,3,IF(N(I39)>=Indicators!$L$37,2,1)))),IF(N(I39)<=Indicators!$O$37,5,IF(N(I39)<=Indicators!$N$37,4,IF(N(I39)<=Indicators!$M$37,3,IF(N(I39)<=Indicators!$L$37,2,1))))))) | K39: 2 | L39: =IF(Indicators!$D$37="C0","",IF(K39<>"",K39,IF(J39<>"",J39,""))) -> 2 | M39: Low | N39: 2025 | O39: =IF(N39="","",IF(N39<($L$5-H39),"STALE","")) | P39: Sector review (satellite/crop-mapping project as precursor) | Q39: https://www.sis.gov.eg/Story/193871/Digital-transformation-in-agro-sector-reviewed?lang=en-us | R39: The MALR-MCIT satellite/AI crop-mapping project implies emerging structured datasets suitable for AI use, but no evidence of a curated, published AI-ready agricultural dataset was found — assessed level 2.
B40: 3.13 | C40: Machine-readable open agricultural data (share of national ag statistics as open APIs) | D40: C2 | E40: Quantitative threshold | F40: Higher | H40: 2 | J40: =IF(I40="","",IF(Indicators!$H$38<>"Quantitative threshold","",IF(Indicators!$I$38="Higher",IF(N(I40)>=Indicators!$O$38,5,IF(N(I40)>=Indicators!$N$38,4,IF(N(I40)>=Indicators!$M$38,3,IF(N(I40)>=Indicators!$L$38,2,1)))),IF(N(I40)<=Indicators!$O$38,5,IF(N(I40)<=Indicators!$N$38,4,IF(N(I40)<=Indicators!$M$38,3,IF(N(I40)<=Indicators!$L$38,2,1))))))) | K40: 1 | L40: =IF(Indicators!$D$38="C0","",IF(K40<>"",K40,IF(J40<>"",J40,""))) -> 1 | M40: Low | N40: 2025 | O40: =IF(N40="","",IF(N40<($L$5-H40),"STALE","")) | P40: Sector review (no evidence of open agricultural-statistics APIs) | R40: New quantitative indicator (thresholds L2=20, L3=40, L4=60, L5=80). No evidence was found of Egypt publishing national agricultural statistics via open, machine-readable APIs; MALR/CAPMAS agricultural census and statistical data appear to be published in conventional report/PDF form rather than API-accessible formats — assessed level 1 (below L2 threshold; no confirmed open-API provision), consistent with the broader Open Data Inventory data gap (indicator 3.2).
B41: 4.1 | C41: Data protection/privacy law | D41: C3 | E41: Anchored capability rubric | F41: N/A | G41: YES | H41: 3 | J41: =IF(I41="","",IF(Indicators!$H$39<>"Quantitative threshold","",IF(Indicators!$I$39="Higher",IF(N(I41)>=Indicators!$O$39,5,IF(N(I41)>=Indicators!$N$39,4,IF(N(I41)>=Indicators!$M$39,3,IF(N(I41)>=Indicators!$L$39,2,1)))),IF(N(I41)<=Indicators!$O$39,5,IF(N(I41)<=Indicators!$N$39,4,IF(N(I41)<=Indicators!$M$39,3,IF(N(I41)<=Indicators!$L$39,2,1))))))) | K41: 4 | L41: =IF(Indicators!$D$39="C0","",IF(K41<>"",K41,IF(J41<>"",J41,""))) -> 4 | M41: High | N41: 2020 | O41: =IF(N41="","",IF(N41<($L$5-H41),"STALE","")) -> STALE | P41: Personal Data Protection Law No. 151/2020 | Q41: https://www.acc.com/sites/default/files/program-materials/upload/Data%20Protection%20Law%20-%20Egypt%20-%20EN%20-%20MBH.PDF | R41: CORE GATE. Egypt's PDPL (Law 151/2020) is in force, covering electronic processing of personal data with carve-outs for national security/judicial/media; comprehensive general law but implementing regulations and enforcement track record still maturing — assessed level 4.
B42: 4.2 | C42: Cybersecurity legal framework (ITU GCI) | D42: C3 | E42: Quantitative threshold | F42: Higher | G42: YES | H42: 3 | I42: 100 | J42: =IF(I42="","",IF(Indicators!$H$40<>"Quantitative threshold","",IF(Indicators!$I$40="Higher",IF(N(I42)>=Indicators!$O$40,5,IF(N(I42)>=Indicators!$N$40,4,IF(N(I42)>=Indicators!$M$40,3,IF(N(I42)>=Indicators!$L$40,2,1)))),IF(N(I42)<=Indicators!$O$40,5,IF(N(I42)<=Indicators!$N$40,4,IF(N(I42)<=Indicators!$M$40,3,IF(N(I42)<=Indicators!$L$40,2,1))))))) -> 5 | L42: =IF(Indicators!$D$40="C0","",IF(K42<>"",K42,IF(J42<>"",J42,""))) -> 5 | M42: High | N42: 2024 | O42: =IF(N42="","",IF(N42<($L$5-H42),"STALE","")) | P42: ITU Global Cybersecurity Index 2024 | Q42: https://www.itu.int/epublications/publication/global-cybersecurity-index-2024 | R42: CORE GATE. Egypt scored a perfect 100/100 in the ITU GCI 2024, Tier 1 'Role-Modelling' status, with 20/20 across all five pillars including the legal-measures pillar; up from 95.48 in the 2020 edition.
B43: 4.3 | C43: Government AI Readiness Index | D43: C3 | E43: Quantitative threshold | F43: Higher | H43: 3 | I43: 57.5 | J43: =IF(I43="","",IF(Indicators!$H$41<>"Quantitative threshold","",IF(Indicators!$I$41="Higher",IF(N(I43)>=Indicators!$O$41,5,IF(N(I43)>=Indicators!$N$41,4,IF(N(I43)>=Indicators!$M$41,3,IF(N(I43)>=Indicators!$L$41,2,1)))),IF(N(I43)<=Indicators!$O$41,5,IF(N(I43)<=Indicators!$N$41,4,IF(N(I43)<=Indicators!$M$41,3,IF(N(I43)<=Indicators!$L$41,2,1))))))) -> 3 | L43: =IF(Indicators!$D$41="C0","",IF(K43<>"",K43,IF(J43<>"",J43,""))) -> 3 | M43: High | N43: 2025 | O43: =IF(N43="","",IF(N43<($L$5-H43),"STALE","")) | P43: Oxford Insights Government AI Readiness Index 2025 | Q43: https://english.ahram.org.eg/NewsContent/3/1239/560268/Business/Tech/Egypt-tops-Africa-in-AI-readiness,-ranks-st-global.aspx | R43: Egypt scored 57.5 and ranked 51st globally (1st in Africa, 4th in MENA) in the 2025 Oxford Insights Government AI Readiness Index, up 14 places from 65th (score 55.63) in the 2024 edition.
...

Sheet Blank Template
B2: [Country name] — DAMM v1.4 assessment
B3: Live scoring. Edit columns I–R. Columns J, L, O are formulas.
B5: Assessment mode | E5: Assessor | H5: Mandate date | K5: Reference year | L5: 2025
B7: ID | C7: Indicator | D7: Pillar | E7: Method | F7: Dir. | G7: Core gate | H7: Max age | I7: Value | J7: Machine L (auto) | K7: Assessor L | L7: Effective L | M7: Confidence | N7: Year | O7: Stale? | P7: Source | Q7: URL | R7: Notes / dissent
B8: 1.1 | C8: Agriculture value added per worker (constant 2015 USD) | D8: C0 | E8: Context profile (not aggregated) | F8: N/A | H8: 3 | J8: =IF(I8="","",IF(Indicators!$H$6<>"Quantitative threshold","",IF(Indicators!$I$6="Higher",IF(N(I8)>=Indicators!$O$6,5,IF(N(I8)>=Indicators!$N$6,4,IF(N(I8)>=Indicators!$M$6,3,IF(N(I8)>=Indicators!$L$6,2,1)))),IF(N(I8)<=Indicators!$O$6,5,IF(N(I8)<=Indicators!$N$6,4,IF(N(I8)<=Indicators!$M$6,3,IF(N(I8)<=Indicators!$L$6,2,1))))))) | L8: =IF(Indicators!$D$6="C0","",IF(K8<>"",K8,IF(J8<>"",J8,""))) | O8: =IF(N8="","",IF(N8<($L$5-H8),"STALE",""))
B9: 1.2 | C9: Cereal yield (kg per hectare) | D9: C0 | E9: Context profile (not aggregated) | F9: N/A | H9: 3 | J9: =IF(I9="","",IF(Indicators!$H$7<>"Quantitative threshold","",IF(Indicators!$I$7="Higher",IF(N(I9)>=Indicators!$O$7,5,IF(N(I9)>=Indicators!$N$7,4,IF(N(I9)>=Indicators!$M$7,3,IF(N(I9)>=Indicators!$L$7,2,1)))),IF(N(I9)<=Indicators!$O$7,5,IF(N(I9)<=Indicators!$N$7,4,IF(N(I9)<=Indicators!$M$7,3,IF(N(I9)<=Indicators!$L$7,2,1))))))) | L9: =IF(Indicators!$D$7="C0","",IF(K9<>"",K9,IF(J9<>"",J9,""))) | O9: =IF(N9="","",IF(N9<($L$5-H9),"STALE",""))
B10: 1.3 | C10: Employment in agriculture (% of total employment) | D10: C0 | E10: Context profile (not aggregated) | F10: N/A | H10: 3 | J10: =IF(I10="","",IF(Indicators!$H$8<>"Quantitative threshold","",IF(Indicators!$I$8="Higher",IF(N(I10)>=Indicators!$O$8,5,IF(N(I10)>=Indicators!$N$8,4,IF(N(I10)>=Indicators!$M$8,3,IF(N(I10)>=Indicators!$L$8,2,1)))),IF(N(I10)<=Indicators!$O$8,5,IF(N(I10)<=Indicators!$N$8,4,IF(N(I10)<=Indicators!$M$8,3,IF(N(I10)<=Indicators!$L$8,2,1))))))) | L10: =IF(Indicators!$D$8="C0","",IF(K10<>"",K10,IF(J10<>"",J10,""))) | O10: =IF(N10="","",IF(N10<($L$5-H10),"STALE",""))
B11: 1.4 | C11: Food production index (2014-2016 = 100) | D11: C0 | E11: Context profile (not aggregated) | F11: N/A | H11: 3 | J11: =IF(I11="","",IF(Indicators!$H$9<>"Quantitative threshold","",IF(Indicators!$I$9="Higher",IF(N(I11)>=Indicators!$O$9,5,IF(N(I11)>=Indicators!$N$9,4,IF(N(I11)>=Indicators!$M$9,3,IF(N(I11)>=Indicators!$L$9,2,1)))),IF(N(I11)<=Indicators!$O$9,5,IF(N(I11)<=Indicators!$N$9,4,IF(N(I11)<=Indicators!$M$9,3,IF(N(I11)<=Indicators!$L$9,2,1))))))) | L11: =IF(Indicators!$D$9="C0","",IF(K11<>"",K11,IF(J11<>"",J11,""))) | O11: =IF(N11="","",IF(N11<($L$5-H11),"STALE",""))
B12: 1.5 | C12: Post-harvest loss rate (%) | D12: C0 | E12: Context profile (not aggregated) | F12: N/A | H12: 2 | J12: =IF(I12="","",IF(Indicators!$H$10<>"Quantitative threshold","",IF(Indicators!$I$10="Higher",IF(N(I12)>=Indicators!$O$10,5,IF(N(I12)>=Indicators!$N$10,4,IF(N(I12)>=Indicators!$M$10,3,IF(N(I12)>=Indicators!$L$10,2,1)))),IF(N(I12)<=Indicators!$O$10,5,IF(N(I12)<=Indicators!$N$10,4,IF(N(I12)<=Indicators!$M$10,3,IF(N(I12)<=Indicators!$L$10,2,1))))))) | L12: =IF(Indicators!$D$10="C0","",IF(K12<>"",K12,IF(J12<>"",J12,""))) | O12: =IF(N12="","",IF(N12<($L$5-H12),"STALE",""))
B13: 1.6 | C13: Smallholder access to formal markets (%) | D13: C0 | E13: Context profile (not aggregated) | F13: N/A | H13: 2 | J13: =IF(I13="","",IF(Indicators!$H$11<>"Quantitative threshold","",IF(Indicators!$I$11="Higher",IF(N(I13)>=Indicators!$O$11,5,IF(N(I13)>=Indicators!$N$11,4,IF(N(I13)>=Indicators!$M$11,3,IF(N(I13)>=Indicators!$L$11,2,1)))),IF(N(I13)<=Indicators!$O$11,5,IF(N(I13)<=Indicators!$N$11,4,IF(N(I13)<=Indicators!$M$11,3,IF(N(I13)<=Indicators!$L$11,2,1))))))) | L13: =IF(Indicators!$D$11="C0","",IF(K13<>"",K13,IF(J13<>"",J13,""))) | O13: =IF(N13="","",IF(N13<($L$5-H13),"STALE",""))
B14: 1.7 | C14: Agricultural credit access (% of farmers) | D14: C0 | E14: Context profile (not aggregated) | F14: N/A | H14: 2 | J14: =IF(I14="","",IF(Indicators!$H$12<>"Quantitative threshold","",IF(Indicators!$I$12="Higher",IF(N(I14)>=Indicators!$O$12,5,IF(N(I14)>=Indicators!$N$12,4,IF(N(I14)>=Indicators!$M$12,3,IF(N(I14)>=Indicators!$L$12,2,1)))),IF(N(I14)<=Indicators!$O$12,5,IF(N(I14)<=Indicators!$N$12,4,IF(N(I14)<=Indicators!$M$12,3,IF(N(I14)<=Indicators!$L$12,2,1))))))) | L14: =IF(Indicators!$D$12="C0","",IF(K14<>"",K14,IF(J14<>"",J14,""))) | O14: =IF(N14="","",IF(N14<($L$5-H14),"STALE",""))
B15: 1.8 | C15: Farmers using climate-smart/sustainable practices (%) | D15: C0 | E15: Context profile (not aggregated) | F15: N/A | H15: 2 | J15: =IF(I15="","",IF(Indicators!$H$13<>"Quantitative threshold","",IF(Indicators!$I$13="Higher",IF(N(I15)>=Indicators!$O$13,5,IF(N(I15)>=Indicators!$N$13,4,IF(N(I15)>=Indicators!$M$13,3,IF(N(I15)>=Indicators!$L$13,2,1)))),IF(N(I15)<=Indicators!$O$13,5,IF(N(I15)<=Indicators!$N$13,4,IF(N(I15)<=Indicators!$M$13,3,IF(N(I15)<=Indicators!$L$13,2,1))))))) | L15: =IF(Indicators!$D$13="C0","",IF(K15<>"",K15,IF(J15<>"",J15,""))) | O15: =IF(N15="","",IF(N15<($L$5-H15),"STALE",""))
B16: 1.9 | C16: National innovation/extension programs with digital component | D16: C4 | E16: Anchored capability rubric | F16: N/A | H16: 2 | J16: =IF(I16="","",IF(Indicators!$H$14<>"Quantitative threshold","",IF(Indicators!$I$14="Higher",IF(N(I16)>=Indicators!$O$14,5,IF(N(I16)>=Indicators!$N$14,4,IF(N(I16)>=Indicators!$M$14,3,IF(N(I16)>=Indicators!$L$14,2,1)))),IF(N(I16)<=Indicators!$O$14,5,IF(N(I16)<=Indicators!$N$14,4,IF(N(I16)<=Indicators!$M$14,3,IF(N(I16)<=Indicators!$L$14,2,1))))))) | L16: =IF(Indicators!$D$14="C0","",IF(K16<>"",K16,IF(J16<>"",J16,""))) | O16: =IF(N16="","",IF(N16<($L$5-H16),"STALE",""))
B17: 2.1 | C17: Rural population covered by at least 3G (%) | D17: C1 | E17: Quantitative threshold | F17: Higher | G17: YES | H17: 3 | J17: =IF(I17="","",IF(Indicators!$H$15<>"Quantitative threshold","",IF(Indicators!$I$15="Higher",IF(N(I17)>=Indicators!$O$15,5,IF(N(I17)>=Indicators!$N$15,4,IF(N(I17)>=Indicators!$M$15,3,IF(N(I17)>=Indicators!$L$15,2,1)))),IF(N(I17)<=Indicators!$O$15,5,IF(N(I17)<=Indicators!$N$15,4,IF(N(I17)<=Indicators!$M$15,3,IF(N(I17)<=Indicators!$L$15,2,1))))))) | L17: =IF(Indicators!$D$15="C0","",IF(K17<>"",K17,IF(J17<>"",J17,""))) | O17: =IF(N17="","",IF(N17<($L$5-H17),"STALE",""))
B18: 2.2 | C18: Rural population covered by at least 4G (%) | D18: C1 | E18: Quantitative threshold | F18: Higher | H18: 3 | J18: =IF(I18="","",IF(Indicators!$H$16<>"Quantitative threshold","",IF(Indicators!$I$16="Higher",IF(N(I18)>=Indicators!$O$16,5,IF(N(I18)>=Indicators!$N$16,4,IF(N(I18)>=Indicators!$M$16,3,IF(N(I18)>=Indicators!$L$16,2,1)))),IF(N(I18)<=Indicators!$O$16,5,IF(N(I18)<=Indicators!$N$16,4,IF(N(I18)<=Indicators!$M$16,3,IF(N(I18)<=Indicators!$L$16,2,1))))))) | L18: =IF(Indicators!$D$16="C0","",IF(K18<>"",K18,IF(J18<>"",J18,""))) | O18: =IF(N18="","",IF(N18<($L$5-H18),"STALE",""))
B19: 2.3 | C19: Active mobile broadband subscriptions per 100 inhabitants | D19: C1 | E19: Quantitative threshold | F19: Higher | H19: 3 | J19: =IF(I19="","",IF(Indicators!$H$17<>"Quantitative threshold","",IF(Indicators!$I$17="Higher",IF(N(I19)>=Indicators!$O$17,5,IF(N(I19)>=Indicators!$N$17,4,IF(N(I19)>=Indicators!$M$17,3,IF(N(I19)>=Indicators!$L$17,2,1)))),IF(N(I19)<=Indicators!$O$17,5,IF(N(I19)<=Indicators!$N$17,4,IF(N(I19)<=Indicators!$M$17,3,IF(N(I19)<=Indicators!$L$17,2,1))))))) | L19: =IF(Indicators!$D$17="C0","",IF(K19<>"",K19,IF(J19<>"",J19,""))) | O19: =IF(N19="","",IF(N19<($L$5-H19),"STALE",""))
